Workbook

Sheet Punisher1
A1: 0 | B1: 0 | C1: 0 | D1: 0 | E1: 0 | F1: 0 | G1: 0 | H1: 0 | I1: 0 | J1: 0 | K1: 0 | L1: 0 | M1: 0 | N1: 0 | O1: 0 | P1: 0 | Q1: 0 | R1: 0 | S1: 0 | T1: 0 | U1: 0 | V1: 0 | W1: 0 | X1: 0 | Y1: 0 | Z1: 0 | AA1: 0 | AB1: 0 | AC1: 0 | AD1: 0
A2: 0 | B2: 0 | C2: 0 | D2: 0 | E2: 0 | F2: 0 | G2: 0 | H2: 0 | I2: 0 | J2: 1 | K2: 1 | L2: 1 | M2: 1 | N2: 1 | O2: 1 | P2: 1 | Q2: 0 | R2: 0 | S2: 0 | T2: 0 | U2: 0 | V2: 0 | W2: 0 | X2: 0 | Y2: 0 | Z2: 0 | AA2: 0 | AB2: 0 | AC2: 0 | AD2: 0
A3: 0 | B3: 0 | C3: 0 | D3: 0 | E3: 0 | F3: 0 | G3: 0 | H3: 1 | I3: 1 | J3: 0 | K3: 0 | L3: 0 | M3: 0 | N3: 0 | O3: 0 | P3: 0 | Q3: 1 | R3: 1 | S3: 1 | T3: 0 | U3: 0 | V3: 0 | W3: 0 | X3: 0 | Y3: 0 | Z3: 0 | AA3: 0 | AB3: 0 | AC3: 0 | AD3: 0
A4: 0 | B4: 0 | C4: 0 | D4: 0 | E4: 0 | F4: 1 | G4: 1 | H4: 0 | I4: 0 | J4: 0 | K4: 0 | L4: 0 | M4: 0 | N4: 0 | O4: 0 | P4: 0 | Q4: 0 | R4: 0 | S4: 0 | T4: 1 | U4: 0 | V4: 0 | W4: 0 | X4: 0 | Y4: 0 | Z4: 0 | AA4: 0 | AB4: 0 | AC4: 0 | AD4: 0
A5: 0 | B5: 0 | C5: 0 | D5: 0 | E5: 1 | F5: 0 | G5: 0 | H5: 0 | I5: 0 | J5: 0 | K5: 0 | L5: 0 | M5: 0 | N5: 0 | O5: 0 | P5: 0 | Q5: 0 | R5: 0 | S5: 0 | T5: 0 | U5: 1 | V5: 0 | W5: 0 | X5: 0 | Y5: 0 | Z5: 0 | AA5: 0 | AB5: 0 | AC5: 0 | AD5: 0
A6: 0 | B6: 0 | C6: 0 | D6: 1 | E6: 0 | F6: 0 | G6: 0 | H6: 0 | I6: 0 | J6: 0 | K6: 0 | L6: 0 | M6: 0 | N6: 0 | O6: 0 | P6: 0 | Q6: 0 | R6: 0 | S6: 0 | T6: 0 | U6: 0 | V6: 1 | W6: 0 | X6: 0 | Y6: 0 | Z6: 0 | AA6: 0 | AB6: 0 | AC6: 0 | AD6: 0
A7: 0 | B7: 0 | C7: 1 | D7: 0 | E7: 0 | F7: 0 | G7: 0 | H7: 0 | I7: 0 | J7: 0 | K7: 0 | L7: 0 | M7: 0 | N7: 0 | O7: 0 | P7: 0 | Q7: 0 | R7: 0 | S7: 0 | T7: 0 | U7: 0 | V7: 0 | W7: 1 | X7: 0 | Y7: 0 | Z7: 0 | AA7: 0 | AB7: 0 | AC7: 0 | AD7: 0
A8: 0 | B8: 1 | C8: 0 | D8: 0 | E8: 0 | F8: 0 | G8: 0 | H8: 0 | I8: 0 | J8: 0 | K8: 0 | L8: 0 | M8: 0 | N8: 0 | O8: 0 | P8: 0 | Q8: 0 | R8: 0 | S8: 0 | T8: 0 | U8: 0 | V8: 0 | W8: 0 | X8: 1 | Y8: 0 | Z8: 0 | AA8: 0 | AB8: 0 | AC8: 0 | AD8: 0
A9: 0 | B9: 1 | C9: 0 | D9: 0 | E9: 0 | F9: 0 | G9: 0 | H9: 0 | I9: 0 | J9: 0 | K9: 0 | L9: 0 | M9: 0 | N9: 0 | O9: 0 | P9: 0 | Q9: 0 | R9: 0 | S9: 0 | T9: 0 | U9: 0 | V9: 0 | W9: 0 | X9: 1 | Y9: 0 | Z9: 0 | AA9: 0 | AB9: 0 | AC9: 0 | AD9: 0
A10: 0 | B10: 1 | C10: 0 | D10: 0 | E10: 0 | F10: 0 | G10: 0 | H10: 0 | I10: 0 | J10: 0 | K10: 0 | L10: 0 | M10: 0 | N10: 0 | O10: 0 | P10: 0 | Q10: 0 | R10: 0 | S10: 0 | T10: 0 | U10: 0 | V10: 0 | W10: 0 | X10: 1 | Y10: 0 | Z10: 0 | AA10: 0 | AB10: 0 | AC10: 0 | AD10: 0
A11: 0 | B11: 1 | C11: 0 | D11: 0 | E11: 0 | F11: 0 | G11: 0 | H11: 0 | I11: 0 | J11: 0 | K11: 0 | L11: 0 | M11: 0 | N11: 0 | O11: 0 | P11: 0 | Q11: 0 | R11: 0 | S11: 0 | T11: 0 | U11: 0 | V11: 0 | W11: 0 | X11: 1 | Y11: 0 | Z11: 0 | AA11: 0 | AB11: 0 | AC11: 0 | AD11: 0
A12: 0 | B12: 1 | C12: 0 | D12: 0 | E12: 0 | F12: 0 | G12: 0 | H12: 0 | I12: 0 | J12: 0 | K12: 0 | L12: 0 | M12: 0 | N12: 0 | O12: 0 | P12: 0 | Q12: 0 | R12: 0 | S12: 0 | T12: 0 | U12: 0 | V12: 0 | W12: 0 | X12: 1 | Y12: 0 | Z12: 0 | AA12: 0 | AB12: 0 | AC12: 0 | AD12: 0
... A27: 0 | B27: 0 | C27: 0 | D27: 0 | E27: 0 | F27: 0 | G27: 0 | H27: 1 | I27: 1 | J27: 0 | K27: 1 | L27: 0 | M27: 1 | N27: 0 | O27: 1 | P27: 0 | Q27: 1 | R27: 1 | S27: 0 | T27: 0 | U27: 0 | V27: 0 | W27: 0 | X27: 0 | Y27: 0 | Z27: 0 | AA27: 0 | AB27: 0 | AC27: 0 | AD27: 0
A28: 0 | B28: 0 | C28: 0 | D28: 0 | E28: 0 | F28: 0 | G28: 0 | H28: 1 | I28: 1 | J28: 0 | K28: 1 | L28: 0 | M28: 1 | N28: 0 | O28: 1 | P28: 0 | Q28: 1 | R28: 1 | S28: 0 | T28: 0 | U28: 0 | V28: 0 | W28: 0 | X28: 0 | Y28: 0 | Z28: 0 | AA28: 0 | AB28: 0 | AC28: 0 | AD28: 0 | AF28: 0 | AG28: blanco
A29: 0 | B29: 0 | C29: 0 | D29: 0 | E29: 0 | F29: 0 | G29: 0 | H29: 1 | I29: 1 | J29: 0 | K29: 1 | L29: 0 | M29: 1 | N29: 0 | O29: 1 | P29: 0 | Q29: 1 | R29: 1 | S29: 0 | T29: 0 | U29: 0 | V29: 0 | W29: 0 | X29: 0 | Y29: 0 | Z29: 0 | AA29: 0 | AB29: 0 | AC29: 0 | AD29: 0 | AF29: 1 | AG29: negro
A30: 0 | B30: 0 | C30: 0 | D30: 0 | E30: 0 | F30: 0 | G30: 0 | H30: 1 | I30: 1 | J30: 0 | K30: 1 | L30: 0 | M30: 1 | N30: 0 | O30: 1 | P30: 0 | Q30: 1 | R30: 1 | S30: 0 | T30: 0 | U30: 0 | V30: 0 | W30: 0 | X30: 0 | Y30: 0 | Z30: 0 | AA30: 0 | AB30: 0 | AC30: 0 | AD30: 0 | AF30: 2 | AG30: rojo
AF31: 3 | AG31: verde
AF32: 4 | AG32: gris

Sheet Punisher1_T
A1: =Punisher1!A1 -> 0 | B1: =Punisher1!A2 -> 0 | C1: =Punisher1!A3 -> 0 | D1: =Punisher1!A4 -> 0 | E1: =Punisher1!A5 -> 0 | F1: =Punisher1!A6 -> 0 | G1: =Punisher1!A7 -> 0 | H1: =Punisher1!A8 -> 0 | I1: =Punisher1!A9 -> 0 | J1: =Punisher1!A10 -> 0 | K1: =Punisher1!A11 -> 0 | L1: =Punisher1!A12 -> 0 | M1: =Punisher1!A13 -> 0 | N1: =Punisher1!A14 -> 0 | O1: =Punisher1!A15 -> 0 | P1: =Punisher1!A16 -> 0 | Q1: =Punisher1!A17 -> 0 | R1: =Punisher1!A18 -> 0 | S1: =Punisher1!A19 -> 0 | T1: =Punisher1!A20 -> 0 | U1: =Punisher1!A21 -> 0 | V1: =Punisher1!A22 -> 0 | W1: =Punisher1!A23 -> 0 | X1: =Punisher1!A24 -> 0 | Y1: =Punisher1!A25 -> 0 | Z1: =Punisher1!A26 -> 0 | AA1: =Punisher1!A27 -> 0 | AB1: =Punisher1!A28 -> 0 | AC1: =Punisher1!A29 -> 0 | AD1: =Punisher1!A30 -> 0
A2: =Punisher1!B1 -> 0 | B2: =Punisher1!B2 -> 0 | C2: =Punisher1!B3 -> 0 | D2: =Punisher1!B4 -> 0 | E2: =Punisher1!B5 -> 0 | F2: =Punisher1!B6 -> 0 | G2: =Punisher1!B7 -> 0 | H2: =Punisher1!B8 -> 1 | I2: =Punisher1!B9 -> 1 | J2: =Punisher1!B10 -> 1 | K2: =Punisher1!B11 -> 1 | L2: =Punisher1!B12 -> 1 | M2: =Punisher1!B13 -> 1 | N2: =Punisher1!B14 -> 1 | O2: =Punisher1!B15 -> 1 | P2: =Punisher1!B16 -> 1 | Q2: =Punisher1!B17 -> 1 | R2: =Punisher1!B18 -> 0 | S2: =Punisher1!B19 -> 0 | T2: =Punisher1!B20 -> 0 | U2: =Punisher1!B21 -> 0 | V2: =Punisher1!B22 -> 0 | W2: =Punisher1!B23 -> 0 | X2: =Punisher1!B24 -> 0 | Y2: =Punisher1!B25 -> 0 | Z2: =Punisher1!B26 -> 0 | AA2: =Punisher1!B27 -> 0 | AB2: =Punisher1!B28 -> 0 | AC2: =Punisher1!B29 -> 0 | AD2: =Punisher1!B30 -> 0
A3: =Punisher1!C1 -> 0 | B3: =Punisher1!C2 -> 0 | C3: =Punisher1!C3 -> 0 | D3: =Punisher1!C4 -> 0 | E3: =Punisher1!C5 -> 0 | F3: =Punisher1!C6 -> 0 | G3: =Punisher1!C7 -> 1 | H3: =Punisher1!C8 -> 0 | I3: =Punisher1!C9 -> 0 | J3: =Punisher1!C10 -> 0 | K3: =Punisher1!C11 -> 0 | L3: =Punisher1!C12 -> 0 | M3: =Punisher1!C13 -> 0 | N3: =Punisher1!C14 -> 0 | O3: =Punisher1!C15 -> 0 | P3: =Punisher1!C16 -> 0 | Q3: =Punisher1!C17 -> 0 | R3: =Punisher1!C18 -> 0 | S3: =Punisher1!C19 -> 0 | T3: =Punisher1!C20 -> 1 | U3: =Punisher1!C21 -> 1 | V3: =Punisher1!C22 -> 0 | W3: =Punisher1!C23 -> 0 | X3: =Punisher1!C24 -> 0 | Y3: =Punisher1!C25 -> 0 | Z3: =Punisher1!C26 -> 0 | AA3: =Punisher1!C27 -> 0 | AB3: =Punisher1!C28 -> 0 | AC3: =Punisher1!C29 -> 0 | AD3: =Punisher1!C30 -> 0
A4: =Punisher1!D1 -> 0 | B4: =Punisher1!D2 -> 0 | C4: =Punisher1!D3 -> 0 | D4: =Punisher1!D4 -> 0 | E4: =Punisher1!D5 -> 0 | F4: =Punisher1!D6 -> 1 | G4: =Punisher1!D7 -> 0 | H4: =Punisher1!D8 -> 0 | I4: =Punisher1!D9 -> 0 | J4: =Punisher1!D10 -> 0 | K4: =Punisher1!D11 -> 0 | L4: =Punisher1!D12 -> 0 | M4: =Punisher1!D13 -> 0 | N4: =Punisher1!D14 -> 0 | O4: =Punisher1!D15 -> 0 | P4: =Punisher1!D16 -> 0 | Q4: =Punisher1!D17 -> 0 | R4: =Punisher1!D18 -> 1 | S4: =Punisher1!D19 -> 1 | T4: =Punisher1!D20 -> 0 | U4: =Punisher1!D21 -> 0 | V4: =Punisher1!D22 -> 0 | W4: =Punisher1!D23 -> 0 | X4: =Punisher1!D24 -> 0 | Y4: =Punisher1!D25 -> 0 | Z4: =Punisher1!D26 -> 0 | AA4: =Punisher1!D27 -> 0 | AB4: =Punisher1!D28 -> 0 | AC4: =Punisher1!D29 -> 0 | AD4: =Punisher1!D30 -> 0
A5: =Punisher1!E1 -> 0 | B5: =Punisher1!E2 -> 0 | C5: =Punisher1!E3 -> 0 | D5: =Punisher1!E4 -> 0 | E5: =Punisher1!E5 -> 1 | F5: =Punisher1!E6 -> 0 | G5: =Punisher1!E7 -> 0 | H5: =Punisher1!E8 -> 0 | I5: =Punisher1!E9 -> 0 | J5: =Punisher1!E10 -> 0 | K5: =Punisher1!E11 -> 0 | L5: =Punisher1!E12 -> 0 | M5: =Punisher1!E13 -> 2 | N5: =Punisher1!E14 -> 2 | O5: =Punisher1!E15 -> 2 | P5: =Punisher1!E16 -> 2 | Q5: =Punisher1!E17 -> 2 | R5: =Punisher1!E18 -> 0 | S5: =Punisher1!E19 -> 0 | T5: =Punisher1!E20 -> 0 | U5: =Punisher1!E21 -> 0 | V5: =Punisher1!E22 -> 0 | W5: =Punisher1!E23 -> 0 | X5: =Punisher1!E24 -> 0 | Y5: =Punisher1!E25 -> 0 | Z5: =Punisher1!E26 -> 0 | AA5: =Punisher1!E27 -> 0 | AB5: =Punisher1!E28 -> 0 | AC5: =Punisher1!E29 -> 0 | AD5: =Punisher1!E30 -> 0
A6: =Punisher1!F1 -> 0 | B6: =Punisher1!F2 -> 0 | C6: =Punisher1!F3 -> 0 | D6: =Punisher1!F4 -> 1 | E6: =Punisher1!F5 -> 0 | F6: =Punisher1!F6 -> 0 | G6: =Punisher1!F7 -> 0 | H6: =Punisher1!F8 -> 0 | I6: =Punisher1!F9 -> 0 | J6: =Punisher1!F10 -> 0 | K6: =Punisher1!F11 -> 0 | L6: =Punisher1!F12 -> 0 | M6: =Punisher1!F13 -> 2 | N6: =Punisher1!F14 -> 2 | O6: =Punisher1!F15 -> 2 | P6: =Punisher1!F16 -> 2 | Q6: =Punisher1!F17 -> 2 | R6: =Punisher1!F18 -> 0 | S6: =Punisher1!F19 -> 0 | T6: =Punisher1!F20 -> 1 | U6: =Punisher1!F21 -> 1 | V6: =Punisher1!F22 -> 0 | W6: =Punisher1!F23 -> 0 | X6: =Punisher1!F24 -> 0 | Y6: =Punisher1!F25 -> 0 | Z6: =Punisher1!F26 -> 0 | AA6: =Punisher1!F27 -> 0 | AB6: =Punisher1!F28 -> 0 | AC6: =Punisher1!F29 -> 0 | AD6: =Punisher1!F30 -> 0
A7: =Punisher1!G1 -> 0 | B7: =Punisher1!G2 -> 0 | C7: =Punisher1!G3 -> 0 | D7: =Punisher1!G4 -> 1 | E7: =Punisher1!G5 -> 0 | F7: =Punisher1!G6 -> 0 | G7: =Punisher1!G7 -> 0 | H7: =Punisher1!G8 -> 0 | I7: =Punisher1!G9 -> 0 | J7: =Punisher1!G10 -> 0 | K7: =Punisher1!G11 -> 0 | L7: =Punisher1!G12 -> 0 | M7: =Punisher1!G13 -> 2 | N7: =Punisher1!G14 -> 2 | O7: =Punisher1!G15 -> 2 | P7: =Punisher1!G16 -> 2 | Q7: =Punisher1!G17 -> 2 | R7: =Punisher1!G18 -> 0 | S7: =Punisher1!G19 -> 0 | T7: =Punisher1!G20 -> 1 | U7: =Punisher1!G21 -> 1 | V7: =Punisher1!G22 -> 0 | W7: =Punisher1!G23 -> 0 | X7: =Punisher1!G24 -> 0 | Y7: =Punisher1!G25 -> 0 | Z7: =Punisher1!G26 -> 0 | AA7: =Punisher1!G27 -> 0 | AB7: =Punisher1!G28 -> 0 | AC7: =Punisher1!G29 -> 0 | AD7: =Punisher1!G30 -> 0
A8: =Punisher1!H1 -> 0 | B8: =Punisher1!H2 -> 0 | C8: =Punisher1!H3 -> 1 | D8: =Punisher1!H4 -> 0 | E8: =Punisher1!H5 -> 0 | F8: =Punisher1!H6 -> 0 | G8: =Punisher1!H7 -> 0 | H8: =Punisher1!H8 -> 0 | I8: =Punisher1!H9 -> 0 | J8: =Punisher1!H10 -> 0 | K8: =Punisher1!H11 -> 0 | L8: =Punisher1!H12 -> 0 | M8: =Punisher1!H13 -> 2 | N8: =Punisher1!H14 -> 2 | O8: =Punisher1!H15 -> 2 | P8: =Punisher1!H16 -> 2 | Q8: =Punisher1!H17 -> 2 | R8: =Punisher1!H18 -> 0 | S8: =Punisher1!H19 -> 0 | T8: =Punisher1!H20 -> 1 | U8: =Punisher1!H21 -> 1 | V8: =Punisher1!H22 -> 1 | W8: =Punisher1!H23 -> 1 | X8: =Punisher1!H24 -> 1 | Y8: =Punisher1!H25 -> 1 | Z8: =Punisher1!H26 -> 1 | AA8: =Punisher1!H27 -> 1 | AB8: =Punisher1!H28 -> 1 | AC8: =Punisher1!H29 -> 1 | AD8: =Punisher1!H30 -> 1
A9: =Punisher1!I1 -> 0 | B9: =Punisher1!I2 -> 0 | C9: =Punisher1!I3 -> 1 | D9: =Punisher1!I4 -> 0 | E9: =Punisher1!I5 -> 0 | F9: =Punisher1!I6 -> 0 | G9: =Punisher1!I7 -> 0 | H9: =Punisher1!I8 -> 0 | I9: =Punisher1!I9 -> 0 | J9: =Punisher1!I10 -> 0 | K9: =Punisher1!I11 -> 0 | L9: =Punisher1!I12 -> 0 | M9: =Punisher1!I13 -> 0 | N9: =Punisher1!I14 -> 0 | O9: =Punisher1!I15 -> 0 | P9: =Punisher1!I16 -> 2 | Q9: =Punisher1!I17 -> 2 | R9: =Punisher1!I18 -> 0 | S9: =Punisher1!I19 -> 0 | T9: =Punisher1!I20 -> 1 | U9: =Punisher1!I21 -> 1 | V9: =Punisher1!I22 -> 1 | W9: =Punisher1!I23 -> 1 | X9: =Punisher1!I24 -> 1 | Y9: =Punisher1!I25 -> 1 | Z9: =Punisher1!I26 -> 1 | AA9: =Punisher1!I27 -> 1 | AB9: =Punisher1!I28 -> 1 | AC9: =Punisher1!I29 -> 1 | AD9: =Punisher1!I30 -> 1
A10: =Punisher1!J1 -> 0 | B10: =Punisher1!J2 -> 1 | C10: =Punisher1!J3 -> 0 | D10: =Punisher1!J4 -> 0 | E10: =Punisher1!J5 -> 0 | F10: =Punisher1!J6 -> 0 | G10: =Punisher1!J7 -> 0 | H10: =Punisher1!J8 -> 0 | I10: =Punisher1!J9 -> 0 | J10: =Punisher1!J10 -> 0 | K10: =Punisher1!J11 -> 0 | L10: =Punisher1!J12 -> 0 | M10: =Punisher1!J13 -> 0 | N10: =Punisher1!J14 -> 0 | O10: =Punisher1!J15 -> 0 | P10: =Punisher1!J16 -> 2 | Q10: =Punisher1!J17 -> 2 | R10: =Punisher1!J18 -> 0 | S10: =Punisher1!J19 -> 0 | T10: =Punisher1!J20 -> 0 | U10: =Punisher1!J21 -> 0 | V10: =Punisher1!J22 -> 0 | W10: =Punisher1!J23 -> 0 | X10: =Punisher1!J24 -> 0 | Y10: =Punisher1!J25 -> 0 | Z10: =Punisher1!J26 -> 0 | AA10: =Punisher1!J27 -> 0 | AB10: =Punisher1!J28 -> 0 | AC10: =Punisher1!J29 -> 0 | AD10: =Punisher1!J30 -> 0
A11: =Punisher1!K1 -> 0 | B11: =Punisher1!K2 -> 1 | C11: =Punisher1!K3 -> 0 | D11: =Punisher1!K4 -> 0 | E11: =Punisher1!K5 -> 0 | F11: =Punisher1!K6 -> 0 | G11: =Punisher1!K7 -> 0 | H11: =Punisher1!K8 -> 0 | I11: =Punisher1!K9 -> 0 | J11: =Punisher1!K10 -> 0 | K11: =Punisher1!K11 -> 0 | L11: =Punisher1!K12 -> 0 | M11: =Punisher1!K13 -> 0 | N11: =Punisher1!K14 -> 0 | O11: =Punisher1!K15 -> 0 | P11: =Punisher1!K16 -> 0 | Q11: =Punisher1!K17 -> 0 | R11: =Punisher1!K18 -> 0 | S11: =Punisher1!K19 -> 0 | T11: =Punisher1!K20 -> 0 | U11: =Punisher1!K21 -> 0 | V11: =Punisher1!K22 -> 1 | W11: =Punisher1!K23 -> 1 | X11: =Punisher1!K24 -> 1 | Y11: =Punisher1!K25 -> 1 | Z11: =Punisher1!K26 -> 1 | AA11: =Punisher1!K27 -> 1 | AB11: =Punisher1!K28 -> 1 | AC11: =Punisher1!K29 -> 1 | AD11: =Punisher1!K30 -> 1
A12: =Punisher1!L1 -> 0 | B12: =Punisher1!L2 -> 1 | C12: =Punisher1!L3 -> 0 | D12: =Punisher1!L4 -> 0 | E12: =Punisher1!L5 -> 0 | F12: =Punisher1!L6 -> 0 | G12: =Punisher1!L7 -> 0 | H12: =Punisher1!L8 -> 0 | I12: =Punisher1!L9 -> 0 | J12: =Punisher1!L10 -> 0 | K12: =Punisher1!L11 -> 0 | L12: =Punisher1!L12 -> 0 | M12: =Punisher1!L13 -> 0 | N12: =Punisher1!L14 -> 0 | O12: =Punisher1!L15 -> 0 | P12: =Punisher1!L16 -> 0 | Q12: =Punisher1!L17 -> 0 | R12: =Punisher1!L18 -> 0 | S12: =Punisher1!L19 -> 1 | T12: =Punisher1!L20 -> 1 | U12: =Punisher1!L21 -> 0 | V12: =Punisher1!L22 -> 0 | W12: =Punisher1!L23 -> 0 | X12: =Punisher1!L24 -> 0 | Y12: =Punisher1!L25 -> 0 | Z12: =Punisher1!L26 -> 0 | AA12: =Punisher1!L27 -> 0 | AB12: =Punisher1!L28 -> 0 | AC12: =Punisher1!L29 -> 0 | AD12: =Punisher1!L30 -> 0
A13: =Punisher1!M1 -> 0 | B13: =Punisher1!M2 -> 1 | C13: =Punisher1!M3 -> 0 | D13: =Punisher1!M4 -> 0 | E13: =Punisher1!M5 -> 0 | F13: =Punisher1!M6 -> 0 | G13: =Punisher1!M7 -> 0 | H13: =Punisher1!M8 -> 0 | I13: =Punisher1!M9 -> 0 | J13: =Punisher1!M10 -> 0 | K13: =Punisher1!M11 -> 0 | L13: =Punisher1!M12 -> 0 | M13: =Punisher1!M13 -> 0 | N13: =Punisher1!M14 -> 0 | O13: =Punisher1!M15 -> 0 | P13: =Punisher1!M16 -> 0 | Q13: =Punisher1!M17 -> 0 | R13: =Punisher1!M18 -> 1 | S13: =Punisher1!M19 -> 0 | T13: =Punisher1!M20 -> 0 | U13: =Punisher1!M21 -> 0 | V13: =Punisher1!M22 -> 1 | W13: =Punisher1!M23 -> 1 | X13: =Punisher1!M24 -> 1 | Y13: =Punisher1!M25 -> 1 | Z13: =Punisher1!M26 -> 1 | AA13: =Punisher1!M27 -> 1 | AB13: =Punisher1!M28 -> 1 | AC13: =Punisher1!M29 -> 1 | AD13: =Punisher1!M30 -> 1
A14: =Punisher1!N1 -> 0 | B14: =Punisher1!N2 -> 1 | C14: =Punisher1!N3 -> 0 | D14: =Punisher1!N4 -> 0 | E14: =Punisher1!N5 -> 0 | F14: =Punisher1!N6 -> 0 | G14: =Punisher1!N7 -> 0 | H14: =Punisher1!N8 -> 0 | I14: =Punisher1!N9 -> 0 | J14: =Punisher1!N10 -> 0 | K14: =Punisher1!N11 -> 0 | L14: =Punisher1!N12 -> 0 | M14: =Punisher1!N13 -> 0 | N14: =Punisher1!N14 -> 0 | O14: =Punisher1!N15 -> 0 | P14: =Punisher1!N16 -> 0 | Q14: =Punisher1!N17 -> 0 | R14: =Punisher1!N18 -> 0 | S14: =Punisher1!N19 -> 1 | T14: =Punisher1!N20 -> 1 | U14: =Punisher1!N21 -> 0 | V14: =Punisher1!N22 -> 0 | W14: =Punisher1!N23 -> 0 | X14: =Punisher1!N24 -> 0 | Y14: =Punisher1!N25 -> 0 | Z14: =Punisher1!N26 -> 0 | AA14: =Punisher1!N27 -> 0 | AB14: =Punisher1!N28 -> 0 | AC14: =Punisher1!N29 -> 0 | AD14: =Punisher1!N30 -> 0
A15: =Punisher1!O1 -> 0 | B15: =Punisher1!O2 -> 1 | C15: =Punisher1!O3 -> 0 | D15: =Punisher1!O4 -> 0 | E15: =Punisher1!O5 -> 0 | F15: =Punisher1!O6 -> 0 | G15: =Punisher1!O7 -> 0 | H15: =Punisher1!O8 -> 0 | I15: =Punisher1!O9 -> 0 | J15: =Punisher1!O10 -> 0 | K15: =Punisher1!O11 -> 0 | L15: =Punisher1!O12 -> 0 | M15: =Punisher1!O13 -> 0 | N15: =Punisher1!O14 -> 0 | O15: =Punisher1!O15 -> 0 | P15: =Punisher1!O16 -> 0 | Q15: =Punisher1!O17 -> 0 | R15: =Punisher1!O18 -> 0 | S15: =Punisher1!O19 -> 0 | T15: =Punisher1!O20 -> 0 | U15: =Punisher1!O21 -> 0 | V15: =Punisher1!O22 -> 1 | W15: =Punisher1!O23 -> 1 | X15: =Punisher1!O24 -> 1 | Y15: =Punisher1!O25 -> 1 | Z15: =Punisher1!O26 -> 1 | AA15: =Punisher1!O27 -> 1 | AB15: =Punisher1!O28 -> 1 | AC15: =Punisher1!O29 -> 1 | AD15: =Punisher1!O30 -> 1
A16: =Punisher1!P1 -> 0 | B16: =Punisher1!P2 -> 1 | C16: =Punisher1!P3 -> 0 | D16: =Punisher1!P4 -> 0 | E16: =Punisher1!P5 -> 0 | F16: =Punisher1!P6 -> 0 | G16: =Punisher1!P7 -> 0 | H16: =Punisher1!P8 -> 0 | I16: =Punisher1!P9 -> 0 | J16: =Punisher1!P10 -> 0 | K16: =Punisher1!P11 -> 0 | L16: =Punisher1!P12 -> 0 | M16: =Punisher1!P13 -> 0 | N16: =Punisher1!P14 -> 0 | O16: =Punisher1!P15 -> 0 | P16: =Punisher1!P16 -> 2 | Q16: =Punisher1!P17 -> 2 | R16: =Punisher1!P18 -> 0 | S16: =Punisher1!P19 -> 0 | T16: =Punisher1!P20 -> 0 | U16: =Punisher1!P21 -> 0 | V16: =Punisher1!P22 -> 0 | W16: =Punisher1!P23 -> 0 | X16: =Punisher1!P24 -> 0 | Y16: =Punisher1!P25 -> 0 | Z16: =Punisher1!P26 -> 0 | AA16: =Punisher1!P27 -> 0 | AB16: =Punisher1!P28 -> 0 | AC16: =Punisher1!P29 -> 0 | AD16: =Punisher1!P30 -> 0
A17: =Punisher1!Q1 -> 0 | B17: =Punisher1!Q2 -> 0 | C17: =Punisher1!Q3 -> 1 | D17: =Punisher1!Q4 -> 0 | E17: =Punisher1!Q5 -> 0 | F17: =Punisher1!Q6 -> 0 | G17: =Punisher1!Q7 -> 0 | H17: =Punisher1!Q8 -> 0 | I17: =Punisher1!Q9 -> 0 | J17: =Punisher1!Q10 -> 0 | K17: =Punisher1!Q11 -> 0 | L17: =Punisher1!Q12 -> 0 | M17: =Punisher1!Q13 -> 0 | N17: =Punisher1!Q14 -> 0 | O17: =Punisher1!Q15 -> 0 | P17: =Punisher1!Q16 -> 2 | Q17: =Punisher1!Q17 -> 2 | R17: =Punisher1!Q18 -> 0 | S17: =Punisher1!Q19 -> 0 | T17: =Punisher1!Q20 -> 1 | U17: =Punisher1!Q21 -> 1 | V17: =Punisher1!Q22 -> 1 | W17: =Punisher1!Q23 -> 1 | X17: =Punisher1!Q24 -> 1 | Y17: =Punisher1!Q25 -> 1 | Z17: =Punisher1!Q26 -> 1 | AA17: =Punisher1!Q27 -> 1 | AB17: =Punisher1!Q28 -> 1 | AC17: =Punisher1!Q29 -> 1 | AD17: =Punisher1!Q30 -> 1
A18: =Punisher1!R1 -> 0 | B18: =Punisher1!R2 -> 0 | C18: =Punisher1!R3 -> 1 | D18: =Punisher1!R4 -> 0 | E18: =Punisher1!R5 -> 0 | F18: =Punisher1!R6 -> 0 | G18: =Punisher1!R7 -> 0 | H18: =Punisher1!R8 -> 0 | I18: =Punisher1!R9 -> 0 | J18: =Punisher1!R10 -> 0 | K18: =Punisher1!R11 -> 0 | L18: =Punisher1!R12 -> 0 | M18: =Punisher1!R13 -> 0 | N18: =Punisher1!R14 -> 0 | O18: =Punisher1!R15 -> 0 | P18: =Punisher1!R16 -> 2 | Q18: =Punisher1!R17 -> 2 | R18: =Punisher1!R18 -> 0 | S18: =Punisher1!R19 -> 0 | T18: =Punisher1!R20 -> 1 | U18: =Punisher1!R21 -> 1 | V18: =Punisher1!R22 -> 1 | W18: =Punisher1!R23 -> 1 | X18: =Punisher1!R24 -> 1 | Y18: =Punisher1!R25 -> 1 | Z18: =Punisher1!R26 -> 1 | AA18: =Punisher1!R27 -> 1 | AB18: =Punisher1!R28 -> 1 | AC18: =Punisher1!R29 -> 1 | AD18: =Punisher1!R30 -> 1
A19: =Punisher1!S1 -> 0 | B19: =Punisher1!S2 -> 0 | C19: =Punisher1!S3 -> 1 | D19: =Punisher1!S4 -> 0 | E19: =Punisher1!S5 -> 0 | F19: =Punisher1!S6 -> 0 | G19: =Punisher1!S7 -> 0 | H19: =Punisher1!S8 -> 0 | I19: =Punisher1!S9 -> 0 | J19: =Punisher1!S10 -> 0 | K19: =Punisher1!S11 -> 0 | L19: =Punisher1!S12 -> 0 | M19: =Punisher1!S13 -> 2 | N19: =Punisher1!S14 -> 2 | O19: =Punisher1!S15 -> 2 | P19: =Punisher1!S16 -> 2 | Q19: =Punisher1!S17 -> 2 | R19: =Punisher1!S18 -> 0 | S19: =Punisher1!S19 -> 0 | T19: =Punisher1!S20 -> 1 | U19: =Punisher1!S21 -> 1 | V19: =Punisher1!S22 -> 0 | W19: =Punisher1!S23 -> 0 | X19: =Punisher1!S24 -> 0 | Y19: =Punisher1!S25 -> 0 | Z19: =Punisher1!S26 -> 0 | AA19: =Punisher1!S27 -> 0 | AB19: =Punisher1!S28 -> 0 | AC19: =Punisher1!S29 -> 0 | AD19: =Punisher1!S30 -> 0
A20: =Punisher1!T1 -> 0 | B20: =Punisher1!T2 -> 0 | C20: =Punisher1!T3 -> 0 | D20: =Punisher1!T4 -> 1 | E20: =Punisher1!T5 -> 0 | F20: =Punisher1!T6 -> 0 | G20: =Punisher1!T7 -> 0 | H20: =Punisher1!T8 -> 0 | I20: =Punisher1!T9 -> 0 | J20: =Punisher1!T10 -> 0 | K20: =Punisher1!T11 -> 0 | L20: =Punisher1!T12 -> 0 | M20: =Punisher1!T13 -> 2 | N20: =Punisher1!T14 -> 2 | O20: =Punisher1!T15 -> 2 | P20: =Punisher1!T16 -> 2 | Q20: =Punisher1!T17 -> 2 | R20: =Punisher1!T18 -> 0 | S20: =Punisher1!T19 -> 0 | T20: =Punisher1!T20 -> 1 | U20: =Punisher1!T21 -> 1 | V20: =Punisher1!T22 -> 0 | W20: =Punisher1!T23 -> 0 | X20: =Punisher1!T24 -> 0 | Y20: =Punisher1!T25 -> 0 | Z20: =Punisher1!T26 -> 0 | AA20: =Punisher1!T27 -> 0 | AB20: =Punisher1!T28 -> 0 | AC20: =Punisher1!T29 -> 0 | AD20: =Punisher1!T30 -> 0
A21: =Punisher1!U1 -> 0 | B21: =Punisher1!U2 -> 0 | C21: =Punisher1!U3 -> 0 | D21: =Punisher1!U4 -> 0 | E21: =Punisher1!U5 -> 1 | F21: =Punisher1!U6 -> 0 | G21: =Punisher1!U7 -> 0 | H21: =Punisher1!U8 -> 0 | I21: =Punisher1!U9 -> 0 | J21: =Punisher1!U10 -> 0 | K21: =Punisher1!U11 -> 0 | L21: =Punisher1!U12 -> 0 | M21: =Punisher1!U13 -> 2 | N21: =Punisher1!U14 -> 2 | O21: =Punisher1!U15 -> 2 | P21: =Punisher1!U16 -> 2 | Q21: =Punisher1!U17 -> 2 | R21: =Punisher1!U18 -> 0 | S21: =Punisher1!U19 -> 0 | T21: =Punisher1!U20 -> 0 | U21: =Punisher1!U21 -> 0 | V21: =Punisher1!U22 -> 0 | W21: =Punisher1!U23 -> 0 | X21: =Punisher1!U24 -> 0 | Y21: =Punisher1!U25 -> 0 | Z21: =Punisher1!U26 -> 0 | AA21: =Punisher1!U27 -> 0 | AB21: =Punisher1!U28 -> 0 | AC21: =Punisher1!U29 -> 0 | AD21: =Punisher1!U30 -> 0
A22: =Punisher1!V1 -> 0 | B22: =Punisher1!V2 -> 0 | C22: =Punisher1!V3 -> 0 | D22: =Punisher1!V4 -> 0 | E22: =Punisher1!V5 -> 0 | F22: =Punisher1!V6 -> 1 | G22: =Punisher1!V7 -> 0 | H22: =Punisher1!V8 -> 0 | I22: =Punisher1!V9 -> 0 | J22: =Punisher1!V10 -> 0 | K22: =Punisher1!V11 -> 0 | L22: =Punisher1!V12 -> 0 | M22: =Punisher1!V13 -> 0 | N22: =Punisher1!V14 -> 0 | O22: =Punisher1!V15 -> 0 | P22: =Punisher1!V16 -> 0 | Q22: =Punisher1!V17 -> 0 | R22: =Punisher1!V18 -> 1 | S22: =Punisher1!V19 -> 1 | T22: =Punisher1!V20 -> 0 | U22: =Punisher1!V21 -> 0 | V22: =Punisher1!V22 -> 0 | W22: =Punisher1!V23 -> 0 | X22: =Punisher1!V24 -> 0 | Y22: =Punisher1!V25 -> 0 | Z22: =Punisher1!V26 -> 0 | AA22: =Punisher1!V27 -> 0 | AB22: =Punisher1!V28 -> 0 | AC22: =Punisher1!V29 -> 0 | AD22: =Punisher1!V30 -> 0
A23: =Punisher1!W1 -> 0 | B23: =Punisher1!W2 -> 0 | C23: =Punisher1!W3 -> 0 | D23: =Punisher1!W4 -> 0 | E23: =Punisher1!W5 -> 0 | F23: =Punisher1!W6 -> 0 | G23: =Punisher1!W7 -> 1 | H23: =Punisher1!W8 -> 0 | I23: =Punisher1!W9 -> 0 | J23: =Punisher1!W10 -> 0 | K23: =Punisher1!W11 -> 0 | L23: =Punisher1!W12 -> 0 | M23: =Punisher1!W13 -> 0 | N23: =Punisher1!W14 -> 0 | O23: =Punisher1!W15 -> 0 | P23: =Punisher1!W16 -> 0 | Q23: =Punisher1!W17 -> 0 | R23: =Punisher1!W18 -> 0 | S23: =Punisher1!W19 -> 0 | T23: =Punisher1!W20 -> 1 | U23: =Punisher1!W21 -> 1 | V23: =Punisher1!W22 -> 0 | W23: =Punisher1!W23 -> 0 | X23: =Punisher1!W24 -> 0 | Y23: =Punisher1!W25 -> 0 | Z23: =Punisher1!W26 -> 0 | AA23: =Punisher1!W27 -> 0 | AB23: =Punisher1!W28 -> 0 | AC23: =Punisher1!W29 -> 0 | AD23: =Punisher1!W30 -> 0
A24: =Punisher1!X1 -> 0 | B24: =Punisher1!X2 -> 0 | C24: =Punisher1!X3 -> 0 | D24: =Punisher1!X4 -> 0 | E24: =Punisher1!X5 -> 0 | F24: =Punisher1!X6 -> 0 | G24: =Punisher1!X7 -> 0 | H24: =Punisher1!X8 -> 1 | I24: =Punisher1!X9 -> 1 | J24: =Punisher1!X10 -> 1 | K24: =Punisher1!X11 -> 1 | L24: =Punisher1!X12 -> 1 | M24: =Punisher1!X13 -> 1 | N24: =Punisher1!X14 -> 1 | O24: =Punisher1!X15 -> 1 | P24: =Punisher1!X16 -> 1 | Q24: =Punisher1!X17 -> 1 | R24: =Punisher1!X18 -> 0 | S24: =Punisher1!X19 -> 0 | T24: =Punisher1!X20 -> 0 | U24: =Punisher1!X21 -> 0 | V24: =Punisher1!X22 -> 0 | W24: =Punisher1!X23 -> 0 | X24: =Punisher1!X24 -> 0 | Y24: =Punisher1!X25 -> 0 | Z24: =Punisher1!X26 -> 0 | AA24: =Punisher1!X27 -> 0 | AB24: =Punisher1!X28 -> 0 | AC24: =Punisher1!X29 -> 0 | AD24: =Punisher1!X30 -> 0
A25: =Punisher1!Y1 -> 0 | B25: =Punisher1!Y2 -> 0 | C25: =Punisher1!Y3 -> 0 | D25: =Punisher1!Y4 -> 0 | E25: =Punisher1!Y5 -> 0 | F25: =Punisher1!Y6 -> 0 | G25: =Punisher1!Y7 -> 0 | H25: =Punisher1!Y8 -> 0 | I25: =Punisher1!Y9 -> 0 | J25: =Punisher1!Y10 -> 0 | K25: =Punisher1!Y11 -> 0 | L25: =Punisher1!Y12 -> 0 | M25: =Punisher1!Y13 -> 0 | N25: =Punisher1!Y14 -> 0 | O25: =Punisher1!Y15 -> 0 | P25: =Punisher1!Y16 -> 0 | Q25: =Punisher1!Y17 -> 0 | R25: =Punisher1!Y18 -> 0 | S25: =Punisher1!Y19 -> 0 | T25: =Punisher1!Y20 -> 0 | U25: =Punisher1!Y21 -> 0 | V25: =Punisher1!Y22 -> 0 | W25: =Punisher1!Y23 -> 0 | X25: =Punisher1!Y24 -> 0 | Y25: =Punisher1!Y25 -> 0 | Z25: =Punisher1!Y26 -> 0 | AA25: =Punisher1!Y27 -> 0 | AB25: =Punisher1!Y28 -> 0 | AC25: =Punisher1!Y29 -> 0 | AD25: =Punisher1!Y30 -> 0
A26: =Punisher1!Z1 -> 0 | B26: =Punisher1!Z2 -> 0 | C26: =Punisher1!Z3 -> 0 | D26: =Punisher1!Z4 -> 0 | E26: =Punisher1!Z5 -> 0 | F26: =Punisher1!Z6 -> 0 | G26: =Punisher1!Z7 -> 0 | H26: =Punisher1!Z8 -> 0 | I26: =Punisher1!Z9 -> 0 | J26: =Punisher1!Z10 -> 0 | K26: =Punisher1!Z11 -> 0 | L26: =Punisher1!Z12 -> 0 | M26: =Punisher1!Z13 -> 0 | N26: =Punisher1!Z14 -> 0 | O26: =Punisher1!Z15 -> 0 | P26: =Punisher1!Z16 -> 0 | Q26: =Punisher1!Z17 -> 0 | R26: =Punisher1!Z18 -> 0 | S26: =Punisher1!Z19 -> 0 | T26: =Punisher1!Z20 -> 0 | U26: =Punisher1!Z21 -> 0 | V26: =Punisher1!Z22 -> 0 | W26: =Punisher1!Z23 -> 0 | X26: =Punisher1!Z24 -> 0 | Y26: =Punisher1!Z25 -> 0 | Z26: =Punisher1!Z26 -> 0 | AA26: =Punisher1!Z27 -> 0 | AB26: =Punisher1!Z28 -> 0 | AC26: =Punisher1!Z29 -> 0 | AD26: =Punisher1!Z30 -> 0
A27: =Punisher1!AA1 -> 0 | B27: =Punisher1!AA2 -> 0 | C27: =Punisher1!AA3 -> 0 | D27: =Punisher1!AA4 -> 0 | E27: =Punisher1!AA5 -> 0 | F27: =Punisher1!AA6 -> 0 | G27: =Punisher1!AA7 -> 0 | H27: =Punisher1!AA8 -> 0 | I27: =Punisher1!AA9 -> 0 | J27: =Punisher1!AA10 -> 0 | K27: =Punisher1!AA11 -> 0 | L27: =Punisher1!AA12 -> 0 | M27: =Punisher1!AA13 -> 0 | N27: =Punisher1!AA14 -> 0 | O27: =Punisher1!AA15 -> 0 | P27: =Punisher1!AA16 -> 0 | Q27: =Punisher1!AA17 -> 0 | R27: =Punisher1!AA18 -> 0 | S27: =Punisher1!AA19 -> 0 | T27: =Punisher1!AA20 -> 0 | U27: =Punisher1!AA21 -> 0 | V27: =Punisher1!AA22 -> 0 | W27: =Punisher1!AA23 -> 0 | X27: =Punisher1!AA24 -> 0 | Y27: =Punisher1!AA25 -> 0 | Z27: =Punisher1!AA26 -> 0 | AA27: =Punisher1!AA27 -> 0 | AB27: =Punisher1!AA28 -> 0 | AC27: =Punisher1!AA29 -> 0 | AD27: =Punisher1!AA30 -> 0
A28: =Punisher1!AB1 -> 0 | B28: =Punisher1!AB2 -> 0 | C28: =Punisher1!AB3 -> 0 | D28: =Punisher1!AB4 -> 0 | E28: =Punisher1!AB5 -> 0 | F28: =Punisher1!AB6 -> 0 | G28: =Punisher1!AB7 -> 0 | H28: =Punisher1!AB8 -> 0 | I28: =Punisher1!AB9 -> 0 | J28: =Punisher1!AB10 -> 0 | K28: =Punisher1!AB11 -> 0 | L28: =Punisher1!AB12 -> 0 | M28: =Punisher1!AB13 -> 0 | N28: =Punisher1!AB14 -> 0 | O28: =Punisher1!AB15 -> 0 | P28: =Punisher1!AB16 -> 0 | Q28: =Punisher1!AB17 -> 0 | R28: =Punisher1!AB18 -> 0 | S28: =Punisher1!AB19 -> 0 | T28: =Punisher1!AB20 -> 0 | U28: =Punisher1!AB21 -> 0 | V28: =Punisher1!AB22 -> 0 | W28: =Punisher1!AB23 -> 0 | X28: =Punisher1!AB24 -> 0 | Y28: =Punisher1!AB25 -> 0 | Z28: =Punisher1!AB26 -> 0 | AA28: =Punisher1!AB27 -> 0 | AB28: =Punisher1!AB28 -> 0 | AC28: =Punisher1!AB29 -> 0 | AD28: =Punisher1!AB30 -> 0
A29: =Punisher1!AC1 -> 0 | B29: =Punisher1!AC2 -> 0 | C29: =Punisher1!AC3 -> 0 | D29: =Punisher1!AC4 -> 0 | E29: =Punisher1!AC5 -> 0 | F29: =Punisher1!AC6 -> 0 | G29: =Punisher1!AC7 -> 0 | H29: =Punisher1!AC8 -> 0 | I29: =Punisher1!AC9 -> 0 | J29: =Punisher1!AC10 -> 0 | K29: =Punisher1!AC11 -> 0 | L29: =Punisher1!AC12 -> 0 | M29: =Punisher1!AC13 -> 0 | N29: =Punisher1!AC14 -> 0 | O29: =Punisher1!AC15 -> 0 | P29: =Punisher1!AC16 -> 0 | Q29: =Punisher1!AC17 -> 0 | R29: =Punisher1!AC18 -> 0 | S29: =Punisher1!AC19 -> 0 | T29: =Punisher1!AC20 -> 0 | U29: =Punisher1!AC21 -> 0 | V29: =Punisher1!AC22 -> 0 | W29: =Punisher1!AC23 -> 0 | X29: =Punisher1!AC24 -> 0 | Y29: =Punisher1!AC25 -> 0 | Z29: =Punisher1!AC26 -> 0 | AA29: =Punisher1!AC27 -> 0 | AB29: =Punisher1!AC28 -> 0 | AC29: =Punisher1!AC29 -> 0 | AD29: =Punisher1!AC30 -> 0
A30: =Punisher1!AD1 -> 0 | B30: =Punisher1!AD2 -> 0 | C30: =Punisher1!AD3 -> 0 | D30: =Punisher1!AD4 -> 0 | E30: =Punisher1!AD5 -> 0 | F30: =Punisher1!AD6 -> 0 | G30: =Punisher1!AD7 -> 0 | H30: =Punisher1!AD8 -> 0 | I30: =Punisher1!AD9 -> 0 | J30: =Punisher1!AD10 -> 0 | K30: =Punisher1!AD11 -> 0 | L30: =Punisher1!AD12 -> 0 | M30: =Punisher1!AD13 -> 0 | N30: =Punisher1!AD14 -> 0 | O30: =Punisher1!AD15 -> 0 | P30: =Punisher1!AD16 -> 0 | Q30: =Punisher1!AD17 -> 0 | R30: =Punisher1!AD18 -> 0 | S30: =Punisher1!AD19 -> 0 | T30: =Punisher1!AD20 -> 0 | U30: =Punisher1!AD21 -> 0 | V30: =Punisher1!AD22 -> 0 | W30: =Punisher1!AD23 -> 0 | X30: =Punisher1!AD24 -> 0 | Y30: =Punisher1!AD25 -> 0 | Z30: =Punisher1!AD26 -> 0 | AA30: =Punisher1!AD27 -> 0 | AB30: =Punisher1!AD28 -> 0 | AC30: =Punisher1!AD29 -> 0 | AD30: =Punisher1!AD30 -> 0

Sheet Suma_Punisher1_Deadpool2
A1: =Punisher1!A1+Deadpool2!A1 -> 0 | B1: =Punisher1!B1+Deadpool2!B1 -> 0 | C1: =Punisher1!C1+Deadpool2!C1 -> 0 | D1: =Punisher1!D1+Deadpool2!D1 -> 0 | E1: =Punisher1!E1+Deadpool2!E1 -> 0 | F1: =Punisher1!F1+Deadpool2!F1 -> 0 | G1: =Punisher1!G1+Deadpool2!G1 -> 0 | H1: =Punisher1!H1+Deadpool2!H1 -> 0 | ... AD1: =Punisher1!AD1+Deadpool2!AD1 -> 0
A2: =Punisher1!A2+Deadpool2!A2 -> 0 | B2: =Punisher1!B2+Deadpool2!B2 -> 0 | C2: =Punisher1!C2+Deadpool2!C2 -> 0 | D2: =Punisher1!D2+Deadpool2!D2 -> 0 | E2: =Punisher1!E2+Deadpool2!E2 -> 0 | F2: =Punisher1!F2+Deadpool2!F2 -> 0 | G2: =Punisher1!G2+Deadpool2!G2 -> 0 | H2: =Punisher1!H2+Deadpool2!H2 -> 0 | ... AD2: =Punisher1!AD2+Deadpool2!AD2 -> 0
A3: =Punisher1!A3+Deadpool2!A3 -> 0 | B3: =Punisher1!B3+Deadpool2!B3 -> 0 | C3: =Punisher1!C3+Deadpool2!C3 -> 0 | D3: =Punisher1!D3+Deadpool2!D3 -> 0 | E3: =Punisher1!E3+Deadpool2!E3 -> 0 | F3: =Punisher1!F3+Deadpool2!F3 -> 0 | G3: =Punisher1!G3+Deadpool2!G3 -> 0 | H3: =Punisher1!H3+Deadpool2!H3 -> 1 | ... AD3: =Punisher1!AD3+Deadpool2!AD3 -> 0
A4: =Punisher1!A4+Deadpool2!A4 -> 0 | B4: =Punisher1!B4+Deadpool2!B4 -> 0 | C4: =Punisher1!C4+Deadpool2!C4 -> 0 | D4: =Punisher1!D4+Deadpool2!D4 -> 0 | E4: =Punisher1!E4+Deadpool2!E4 -> 0 | F4: =Punisher1!F4+Deadpool2!F4 -> 1 | G4: =Punisher1!G4+Deadpool2!G4 -> 1 | H4: =Punisher1!H4+Deadpool2!H4 -> 0 | ... AD4: =Punisher1!AD4+Deadpool2!AD4 -> 0
A5: =Punisher1!A5+Deadpool2!A5 -> 0 | B5: =Punisher1!B5+Deadpool2!B5 -> 0 | C5: =Punisher1!C5+Deadpool2!C5 -> 0 | D5: =Punisher1!D5+Deadpool2!D5 -> 0 | E5: =Punisher1!E5+Deadpool2!E5 -> 1 | F5: =Punisher1!F5+Deadpool2!F5 -> 0 | G5: =Punisher1!G5+Deadpool2!G5 -> 0 | H5: =Punisher1!H5+Deadpool2!H5 -> 2 | ... AD5: =Punisher1!AD5+Deadpool2!AD5 -> 0
A6: =Punisher1!A6+Deadpool2!A6 -> 0 | B6: =Punisher1!B6+Deadpool2!B6 -> 0 | C6: =Punisher1!C6+Deadpool2!C6 -> 0 | D6: =Punisher1!D6+Deadpool2!D6 -> 1 | E6: =Punisher1!E6+Deadpool2!E6 -> 0 | F6: =Punisher1!F6+Deadpool2!F6 -> 2 | G6: =Punisher1!G6+Deadpool2!G6 -> 2 | H6: =Punisher1!H6+Deadpool2!H6 -> 2 | ... AD6: =Punisher1!AD6+Deadpool2!AD6 -> 0
A7: =Punisher1!A7+Deadpool2!A7 -> 0 | B7: =Punisher1!B7+Deadpool2!B7 -> 0 | C7: =Punisher1!C7+Deadpool2!C7 -> 1 | D7: =Punisher1!D7+Deadpool2!D7 -> 0 | E7: =Punisher1!E7+Deadpool2!E7 -> 2 | F7: =Punisher1!F7+Deadpool2!F7 -> 2 | G7: =Punisher1!G7+Deadpool2!G7 -> 2 | H7: =Punisher1!H7+Deadpool2!H7 -> 2 | ... AD7: =Punisher1!AD7+Deadpool2!AD7 -> 0
A8: =Punisher1!A8+Deadpool2!A8 -> 0 | B8: =Punisher1!B8+Deadpool2!B8 -> 1 | C8: =Punisher1!C8+Deadpool2!C8 -> 0 | D8: =Punisher1!D8+Deadpool2!D8 -> 2 | E8: =Punisher1!E8+Deadpool2!E8 -> 2 | F8: =Punisher1!F8+Deadpool2!F8 -> 2 | G8: =Punisher1!G8+Deadpool2!G8 -> 2 | H8: =Punisher1!H8+Deadpool2!H8 -> 1 | ... AD8: =Punisher1!AD8+Deadpool2!AD8 -> 0
A9: =Punisher1!A9+Deadpool2!A9 -> 0 | B9: =Punisher1!B9+Deadpool2!B9 -> 1 | C9: =Punisher1!C9+Deadpool2!C9 -> 2 | D9: =Punisher1!D9+Deadpool2!D9 -> 2 | E9: =Punisher1!E9+Deadpool2!E9 -> 2 | F9: =Punisher1!F9+Deadpool2!F9 -> 1 | G9: =Punisher1!G9+Deadpool2!G9 -> 1 | H9: =Punisher1!H9+Deadpool2!H9 -> 1 | ... AD9: =Punisher1!AD9+Deadpool2!AD9 -> 0
A10: =Punisher1!A10+Deadpool2!A10 -> 0 | B10: =Punisher1!B10+Deadpool2!B10 -> 3 | C10: =Punisher1!C10+Deadpool2!C10 -> 2 | D10: =Punisher1!D10+Deadpool2!D10 -> 2 | E10: =Punisher1!E10+Deadpool2!E10 -> 2 | F10: =Punisher1!F10+Deadpool2!F10 -> 1 | G10: =Punisher1!G10+Deadpool2!G10 -> 1 | H10: =Punisher1!H10+Deadpool2!H10 -> 1 | ... AD10: =Punisher1!AD10+Deadpool2!AD10 -> 0
A11: =Punisher1!A11+Deadpool2!A11 -> 0 | B11: =Punisher1!B11+Deadpool2!B11 -> 3 | C11: =Punisher1!C11+Deadpool2!C11 -> 2 | D11: =Punisher1!D11+Deadpool2!D11 -> 2 | E11: =Punisher1!E11+Deadpool2!E11 -> 1 | F11: =Punisher1!F11+Deadpool2!F11 -> 1 | G11: =Punisher1!G11+Deadpool2!G11 -> 1 | H11: =Punisher1!H11+Deadpool2!H11 -> 1 | ... AD11: =Punisher1!AD11+Deadpool2!AD11 -> 0
A12: =Punisher1!A12+Deadpool2!A12 -> 0 | B12: =Punisher1!B12+Deadpool2!B12 -> 3 | C12: =Punisher1!C12+Deadpool2!C12 -> 2 | D12: =Punisher1!D12+Deadpool2!D12 -> 2 | E12: =Punisher1!E12+Deadpool2!E12 -> 1 | F12: =Punisher1!F12+Deadpool2!F12 -> 1 | G12: =Punisher1!G12+Deadpool2!G12 -> 1 | H12: =Punisher1!H12+Deadpool2!H12 -> 1 | ... AD12: =Punisher1!AD12+Deadpool2!AD12 -> 0
... A19: =Punisher1!A19+Deadpool2!A19 -> 0 | B19: =Punisher1!B19+Deadpool2!B19 -> 2 | C19: =Punisher1!C19+Deadpool2!C19 -> 2 | D19: =Punisher1!D19+Deadpool2!D19 -> 3 | E19: =Punisher1!E19+Deadpool2!E19 -> 1 | F19: =Punisher1!F19+Deadpool2!F19 -> 1 | G19: =Punisher1!G19+Deadpool2!G19 -> 0 | H19: =Punisher1!H19+Deadpool2!H19 -> 0 | ... AD19: =Punisher1!AD19+Deadpool2!AD19 -> 0
A20: =Punisher1!A20+Deadpool2!A20 -> 0 | B20: =Punisher1!B20+Deadpool2!B20 -> 2 | C20: =Punisher1!C20+Deadpool2!C20 -> 3 | D20: =Punisher1!D20+Deadpool2!D20 -> 2 | E20: =Punisher1!E20+Deadpool2!E20 -> 1 | F20: =Punisher1!F20+Deadpool2!F20 -> 2 | G20: =Punisher1!G20+Deadpool2!G20 -> 2 | H20: =Punisher1!H20+Deadpool2!H20 -> 1 | ... Q20: =Punisher1!Q20+Deadpool2!Q20 -> 2 | S20: =Punisher1!S20+Deadpool2!S20 -> 1 | T20: =Punisher1!T20+Deadpool2!T20 -> 1 | U20: =Punisher1!U20+Deadpool2!U20 -> 0 | V20: =Punisher1!V20+Deadpool2!V20 -> 0 | W20: =Punisher1!W20+Deadpool2!W20 -> 2 | X20: =Punisher1!X20+Deadpool2!X20 -> 1 | Y20: =Punisher1!Y20+Deadpool2!Y20 -> 1 | Z20: =Punisher1!Z20+Deadpool2!Z20 -> 2 | ... AD20: =Punisher1!AD20+Deadpool2!AD20 -> 0
A21: =Punisher1!A21+Deadpool2!A21 -> 0 | B21: =Punisher1!B21+Deadpool2!B21 -> 0 | C21: =Punisher1!C21+Deadpool2!C21 -> 3 | D21: =Punisher1!D21+Deadpool2!D21 -> 2 | E21: =Punisher1!E21+Deadpool2!E21 -> 2 | F21: =Punisher1!F21+Deadpool2!F21 -> 2 | G21: =Punisher1!G21+Deadpool2!G21 -> 2 | H21: =Punisher1!H21+Deadpool2!H21 -> 2 | ... AD21: =Punisher1!AD21+Deadpool2!AD21 -> 0
A22: =Punisher1!A22+Deadpool2!A22 -> 0 | B22: =Punisher1!B22+Deadpool2!B22 -> 0 | C22: =Punisher1!C22+Deadpool2!C22 -> 0 | D22: =Punisher1!D22+Deadpool2!D22 -> 2 | E22: =Punisher1!E22+Deadpool2!E22 -> 2 | F22: =Punisher1!F22+Deadpool2!F22 -> 1 | G22: =Punisher1!G22+Deadpool2!G22 -> 1 | H22: =Punisher1!H22+Deadpool2!H22 -> 2 | ... AD22: =Punisher1!AD22+Deadpool2!AD22 -> 0
A23: =Punisher1!A23+Deadpool2!A23 -> 0 | B23: =Punisher1!B23+Deadpool2!B23 -> 0 | C23: =Punisher1!C23+Deadpool2!C23 -> 0 | D23: =Punisher1!D23+Deadpool2!D23 -> 0 | E23: =Punisher1!E23+Deadpool2!E23 -> 2 | F23: =Punisher1!F23+Deadpool2!F23 -> 2 | G23: =Punisher1!G23+Deadpool2!G23 -> 2 | H23: =Punisher1!H23+Deadpool2!H23 -> 2 | ... AD23: =Punisher1!AD23+Deadpool2!AD23 -> 0
A24: =Punisher1!A24+Deadpool2!A24 -> 0 | B24: =Punisher1!B24+Deadpool2!B24 -> 0 | C24: =Punisher1!C24+Deadpool2!C24 -> 0 | D24: =Punisher1!D24+Deadpool2!D24 -> 0 | E24: =Punisher1!E24+Deadpool2!E24 -> 0 | F24: =Punisher1!F24+Deadpool2!F24 -> 2 | G24: =Punisher1!G24+Deadpool2!G24 -> 2 | H24: =Punisher1!H24+Deadpool2!H24 -> 3 | ... AD24: =Punisher1!AD24+Deadpool2!AD24 -> 0
A25: =Punisher1!A25+Deadpool2!A25 -> 0 | B25: =Punisher1!B25+Deadpool2!B25 -> 0 | C25: =Punisher1!C25+Deadpool2!C25 -> 0 | D25: =Punisher1!D25+Deadpool2!D25 -> 0 | E25: =Punisher1!E25+Deadpool2!E25 -> 0 | F25: =Punisher1!F25+Deadpool2!F25 -> 0 | G25: =Punisher1!G25+Deadpool2!G25 -> 2 | H25: =Punisher1!H25+Deadpool2!H25 -> 3 | ... AD25: =Punisher1!AD25+Deadpool2!AD25 -> 0
A26: =Punisher1!A26+Deadpool2!A26 -> 0 | B26: =Punisher1!B26+Deadpool2!B26 -> 0 | C26: =Punisher1!C26+Deadpool2!C26 -> 0 | D26: =Punisher1!D26+Deadpool2!D26 -> 0 | E26: =Punisher1!E26+Deadpool2!E26 -> 0 | F26: =Punisher1!F26+Deadpool2!F26 -> 0 | G26: =Punisher1!G26+Deadpool2!G26 -> 2 | H26: =Punisher1!H26+Deadpool2!H26 -> 3 | ... AD26: =Punisher1!AD26+Deadpool2!AD26 -> 0
A27: =Punisher1!A27+Deadpool2!A27 -> 0 | B27: =Punisher1!B27+Deadpool2!B27 -> 0 | C27: =Punisher1!C27+Deadpool2!C27 -> 0 | D27: =Punisher1!D27+Deadpool2!D27 -> 0 | E27: =Punisher1!E27+Deadpool2!E27 -> 0 | F27: =Punisher1!F27+Deadpool2!F27 -> 0 | G27: =Punisher1!G27+Deadpool2!G27 -> 0 | H27: =Punisher1!H27+Deadpool2!H27 -> 1 | ... AD27: =Punisher1!AD27+Deadpool2!AD27 -> 0
A28: =Punisher1!A28+Deadpool2!A28 -> 0 | B28: =Punisher1!B28+Deadpool2!B28 -> 0 | C28: =Punisher1!C28+Deadpool2!C28 -> 0 | D28: =Punisher1!D28+Deadpool2!D28 -> 0 | E28: =Punisher1!E28+Deadpool2!E28 -> 0 | F28: =Punisher1!F28+Deadpool2!F28 -> 0 | G28: =Punisher1!G28+Deadpool2!G28 -> 0 | H28: =Punisher1!H28+Deadpool2!H28 -> 1 | ... AD28: =Punisher1!AD28+Deadpool2!AD28 -> 0
A29: =Punisher1!A29+Deadpool2!A29 -> 0 | B29: =Punisher1!B29+Deadpool2!B29 -> 0 | C29: =Punisher1!C29+Deadpool2!C29 -> 0 | D29: =Punisher1!D29+Deadpool2!D29 -> 0 | E29: =Punisher1!E29+Deadpool2!E29 -> 0 | F29: =Punisher1!F29+Deadpool2!F29 -> 0 | G29: =Punisher1!G29+Deadpool2!G29 -> 0 | H29: =Punisher1!H29+Deadpool2!H29 -> 1 | ... AD29: =Punisher1!AD29+Deadpool2!AD29 -> 0
A30: =Punisher1!A30+Deadpool2!A30 -> 0 | B30: =Punisher1!B30+Deadpool2!B30 -> 0 | C30: =Punisher1!C30+Deadpool2!C30 -> 0 | D30: =Punisher1!D30+Deadpool2!D30 -> 0 | E30: =Punisher1!E30+Deadpool2!E30 -> 0 | F30: =Punisher1!F30+Deadpool2!F30 -> 0 | G30: =Punisher1!G30+Deadpool2!G30 -> 0 | H30: =Punisher1!H30+Deadpool2!H30 -> 1 | ... AD30: =Punisher1!AD30+Deadpool2!AD30 -> 0

Sheet Resta_Punisher1_Deadpool2
A1: =Punisher1!A1-Deadpool2!A1 -> 0 | B1: =Punisher1!B1-Deadpool2!B1 -> 0 | C1: =Punisher1!C1-Deadpool2!C1 -> 0 | D1: =Punisher1!D1-Deadpool2!D1 -> 0 | E1: =Punisher1!E1-Deadpool2!E1 -> 0 | F1: =Punisher1!F1-Deadpool2!F1 -> 0 | G1: =Punisher1!G1-Deadpool2!G1 -> 0 | H1: =Punisher1!H1-Deadpool2!H1 -> 0 | ... AD1: =Punisher1!AD1-Deadpool2!AD1 -> 0
A2: =Punisher1!A2-Deadpool2!A2 -> 0 | B2: =Punisher1!B2-Deadpool2!B2 -> 0 | C2: =Punisher1!C2-Deadpool2!C2 -> 0 | D2: =Punisher1!D2-Deadpool2!D2 -> 0 | E2: =Punisher1!E2-Deadpool2!E2 -> 0 | F2: =Punisher1!F2-Deadpool2!F2 -> 0 | G2: =Punisher1!G2-Deadpool2!G2 -> 0 | H2: =Punisher1!H2-Deadpool2!H2 -> 0 | ... AD2: =Punisher1!AD2-Deadpool2!AD2 -> 0
A3: =Punisher1!A3-Deadpool2!A3 -> 0 | B3: =Punisher1!B3-Deadpool2!B3 -> 0 | C3: =Punisher1!C3-Deadpool2!C3 -> 0 | D3: =Punisher1!D3-Deadpool2!D3 -> 0 | E3: =Punisher1!E3-Deadpool2!E3 -> 0 | F3: =Punisher1!F3-Deadpool2!F3 -> 0 | G3: =Punisher1!G3-Deadpool2!G3 -> 0 | H3: =Punisher1!H3-Deadpool2!H3 -> 1 | ... AD3: =Punisher1!AD3-Deadpool2!AD3 -> 0
A4: =Punisher1!A4-Deadpool2!A4 -> 0 | B4: =Punisher1!B4-Deadpool2!B4 -> 0 | C4: =Punisher1!C4-Deadpool2!C4 -> 0 | D4: =Punisher1!D4-Deadpool2!D4 -> 0 | E4: =Punisher1!E4-Deadpool2!E4 -> 0 | F4: =Punisher1!F4-Deadpool2!F4 -> 1 | G4: =Punisher1!G4-Deadpool2!G4 -> 1 | H4: =Punisher1!H4-Deadpool2!H4 -> 0 | ... AD4: =Punisher1!AD4-Deadpool2!AD4 -> 0
A5: =Punisher1!A5-Deadpool2!A5 -> 0 | B5: =Punisher1!B5-Deadpool2!B5 -> 0 | C5: =Punisher1!C5-Deadpool2!C5 -> 0 | D5: =Punisher1!D5-Deadpool2!D5 -> 0 | E5: =Punisher1!E5-Deadpool2!E5 -> 1 | F5: =Punisher1!F5-Deadpool2!F5 -> 0 | G5: =Punisher1!G5-Deadpool2!G5 -> 0 | H5: =Punisher1!H5-Deadpool2!H5 -> -2 | ... AD5: =Punisher1!AD5-Deadpool2!AD5 -> 0
A6: =Punisher1!A6-Deadpool2!A6 -> 0 | B6: =Punisher1!B6-Deadpool2!B6 -> 0 | C6: =Punisher1!C6-Deadpool2!C6 -> 0 | D6: =Punisher1!D6-Deadpool2!D6 -> 1 | E6: =Punisher1!E6-Deadpool2!E6 -> 0 | F6: =Punisher1!F6-Deadpool2!F6 -> -2 | G6: =Punisher1!G6-Deadpool2!G6 -> -2 | H6: =Punisher1!H6-Deadpool2!H6 -> -2 | ... AD6: =Punisher1!AD6-Deadpool2!AD6 -> 0
A7: =Punisher1!A7-Deadpool2!A7 -> 0 | B7: =Punisher1!B7-Deadpool2!B7 -> 0 | C7: =Punisher1!C7-Deadpool2!C7 -> 1 | D7: =Punisher1!D7-Deadpool2!D7 -> 0 | E7: =Punisher1!E7-Deadpool2!E7 -> -2 | F7: =Punisher1!F7-Deadpool2!F7 -> -2 | G7: =Punisher1!G7-Deadpool2!G7 -> -2 | H7: =Punisher1!H7-Deadpool2!H7 -> -2 | ... AD7: =Punisher1!AD7-Deadpool2!AD7 -> 0
A8: =Punisher1!A8-Deadpool2!A8 -> 0 | B8: =Punisher1!B8-Deadpool2!B8 -> 1 | C8: =Punisher1!C8-Deadpool2!C8 -> 0 | D8: =Punisher1!D8-Deadpool2!D8 -> -2 | E8: =Punisher1!E8-Deadpool2!E8 -> -2 | F8: =Punisher1!F8-Deadpool2!F8 -> -2 | G8: =Punisher1!G8-Deadpool2!G8 -> -2 | H8: =Punisher1!H8-Deadpool2!H8 -> -1 | ... AD8: =Punisher1!AD8-Deadpool2!AD8 -> 0
A9: =Punisher1!A9-Deadpool2!A9 -> 0 | B9: =Punisher1!B9-Deadpool2!B9 -> 1 | C9: =Punisher1!C9-Deadpool2!C9 -> -2 | D9: =Punisher1!D9-Deadpool2!D9 -> -2 | E9: =Punisher1!E9-Deadpool2!E9 -> -2 | F9: =Punisher1!F9-Deadpool2!F9 -> -1 | G9: =Punisher1!G9-Deadpool2!G9 -> -1 | H9: =Punisher1!H9-Deadpool2!H9 -> -1 | ... AD9: =Punisher1!AD9-Deadpool2!AD9 -> 0
A10: =Punisher1!A10-Deadpool2!A10 -> 0 | B10: =Punisher1!B10-Deadpool2!B10 -> -1 | C10: =Punisher1!C10-Deadpool2!C10 -> -2 | D10: =Punisher1!D10-Deadpool2!D10 -> -2 | E10: =Punisher1!E10-Deadpool2!E10 -> -2 | F10: =Punisher1!F10-Deadpool2!F10 -> -1 | G10: =Punisher1!G10-Deadpool2!G10 -> -1 | H10: =Punisher1!H10-Deadpool2!H10 -> -1 | ... AD10: =Punisher1!AD10-Deadpool2!AD10 -> 0
A11: =Punisher1!A11-Deadpool2!A11 -> 0 | B11: =Punisher1!B11-Deadpool2!B11 -> -1 | C11: =Punisher1!C11-Deadpool2!C11 -> -2 | D11: =Punisher1!D11-Deadpool2!D11 -> -2 | E11: =Punisher1!E11-Deadpool2!E11 -> -1 | F11: =Punisher1!F11-Deadpool2!F11 -> -1 | G11: =Punisher1!G11-Deadpool2!G11 -> -1 | H11: =Punisher1!H11-Deadpool2!H11 -> -1 | ... AD11: =Punisher1!AD11-Deadpool2!AD11 -> 0
A12: =Punisher1!A12-Deadpool2!A12 -> 0 | B12: =Punisher1!B12-Deadpool2!B12 -> -1 | C12: =Punisher1!C12-Deadpool2!C12 -> -2 | D12: =Punisher1!D12-Deadpool2!D12 -> -2 | E12: =Punisher1!E12-Deadpool2!E12 -> -1 | F12: =Punisher1!F12-Deadpool2!F12 -> -1 | G12: =Punisher1!G12-Deadpool2!G12 -> -1 | H12: =Punisher1!H12-Deadpool2!H12 -> -1 | ... AD12: =Punisher1!AD12-Deadpool2!AD12 -> 0
... A19: =Punisher1!A19-Deadpool2!A19 -> 0 | B19: =Punisher1!B19-Deadpool2!B19 -> -2 | C19: =Punisher1!C19-Deadpool2!C19 -> -2 | D19: =Punisher1!D19-Deadpool2!D19 -> -1 | E19: =Punisher1!E19-Deadpool2!E19 -> -1 | F19: =Punisher1!F19-Deadpool2!F19 -> -1 | G19: =Punisher1!G19-Deadpool2!G19 -> 0 | H19: =Punisher1!H19-Deadpool2!H19 -> 0 | ... AD19: =Punisher1!AD19-Deadpool2!AD19 -> 0
A20: =Punisher1!A20-Deadpool2!A20 -> 0 | B20: =Punisher1!B20-Deadpool2!B20 -> -2 | C20: =Punisher1!C20-Deadpool2!C20 -> -1 | D20: =Punisher1!D20-Deadpool2!D20 -> -2 | E20: =Punisher1!E20-Deadpool2!E20 -> -1 | F20: =Punisher1!F20-Deadpool2!F20 -> 0 | G20: =Punisher1!G20-Deadpool2!G20 -> 0 | H20: =Punisher1!H20-Deadpool2!H20 -> 1 | ... Q20: =Punisher1!Q20-Deadpool2!Q20 -> 0 | S20: =Punisher1!S20-Deadpool2!S20 -> 1 | T20: =Punisher1!T20-Deadpool2!T20 -> 1 | U20: =Punisher1!U20-Deadpool2!U20 -> 0 | V20: =Punisher1!V20-Deadpool2!V20 -> 0 | W20: =Punisher1!W20-Deadpool2!W20 -> 0 | X20: =Punisher1!X20-Deadpool2!X20 -> -1 | Y20: =Punisher1!Y20-Deadpool2!Y20 -> -1 | Z20: =Punisher1!Z20-Deadpool2!Z20 -> -2 | ... AD20: =Punisher1!AD20-Deadpool2!AD20 -> 0
A21: =Punisher1!A21-Deadpool2!A21 -> 0 | B21: =Punisher1!B21-Deadpool2!B21 -> 0 | C21: =Punisher1!C21-Deadpool2!C21 -> -1 | D21: =Punisher1!D21-Deadpool2!D21 -> -2 | E21: =Punisher1!E21-Deadpool2!E21 -> -2 | F21: =Punisher1!F21-Deadpool2!F21 -> 0 | G21: =Punisher1!G21-Deadpool2!G21 -> 0 | H21: =Punisher1!H21-Deadpool2!H21 -> 0 | ... AD21: =Punisher1!AD21-Deadpool2!AD21 -> 0
A22: =Punisher1!A22-Deadpool2!A22 -> 0 | B22: =Punisher1!B22-Deadpool2!B22 -> 0 | C22: =Punisher1!C22-Deadpool2!C22 -> 0 | D22: =Punisher1!D22-Deadpool2!D22 -> -2 | E22: =Punisher1!E22-Deadpool2!E22 -> -2 | F22: =Punisher1!F22-Deadpool2!F22 -> -1 | G22: =Punisher1!G22-Deadpool2!G22 -> -1 | H22: =Punisher1!H22-Deadpool2!H22 -> 0 | ... AD22: =Punisher1!AD22-Deadpool2!AD22 -> 0
A23: =Punisher1!A23-Deadpool2!A23 -> 0 | B23: =Punisher1!B23-Deadpool2!B23 -> 0 | C23: =Punisher1!C23-Deadpool2!C23 -> 0 | D23: =Punisher1!D23-Deadpool2!D23 -> 0 | E23: =Punisher1!E23-Deadpool2!E23 -> -2 | F23: =Punisher1!F23-Deadpool2!F23 -> -2 | G23: =Punisher1!G23-Deadpool2!G23 -> -2 | H23: =Punisher1!H23-Deadpool2!H23 -> 0 | ... AD23: =Punisher1!AD23-Deadpool2!AD23 -> 0
A24: =Punisher1!A24-Deadpool2!A24 -> 0 | B24: =Punisher1!B24-Deadpool2!B24 -> 0 | C24: =Punisher1!C24-Deadpool2!C24 -> 0 | D24: =Punisher1!D24-Deadpool2!D24 -> 0 | E24: =Punisher1!E24-Deadpool2!E24 -> 0 | F24: =Punisher1!F24-Deadpool2!F24 -> -2 | G24: =Punisher1!G24-Deadpool2!G24 -> -2 | H24: =Punisher1!H24-Deadpool2!H24 -> -1 | ... AD24: =Punisher1!AD24-Deadpool2!AD24 -> 0
A25: =Punisher1!A25-Deadpool2!A25 -> 0 | B25: =Punisher1!B25-Deadpool2!B25 -> 0 | C25: =Punisher1!C25-Deadpool2!C25 -> 0 | D25: =Punisher1!D25-Deadpool2!D25 -> 0 | E25: =Punisher1!E25-Deadpool2!E25 -> 0 | F25: =Punisher1!F25-Deadpool2!F25 -> 0 | G25: =Punisher1!G25-Deadpool2!G25 -> -2 | H25: =Punisher1!H25-Deadpool2!H25 -> -1 | ... AD25: =Punisher1!AD25-Deadpool2!AD25 -> 0
A26: =Punisher1!A26-Deadpool2!A26 -> 0 | B26: =Punisher1!B26-Deadpool2!B26 -> 0 | C26: =Punisher1!C26-Deadpool2!C26 -> 0 | D26: =Punisher1!D26-Deadpool2!D26 -> 0 | E26: =Punisher1!E26-Deadpool2!E26 -> 0 | F26: =Punisher1!F26-Deadpool2!F26 -> 0 | G26: =Punisher1!G26-Deadpool2!G26 -> -2 | H26: =Punisher1!H26-Deadpool2!H26 -> -1 | ... AD26: =Punisher1!AD26-Deadpool2!AD26 -> 0
A27: =Punisher1!A27-Deadpool2!A27 -> 0 | B27: =Punisher1!B27-Deadpool2!B27 -> 0 | C27: =Punisher1!C27-Deadpool2!C27 -> 0 | D27: =Punisher1!D27-Deadpool2!D27 -> 0 | E27: =Punisher1!E27-Deadpool2!E27 -> 0 | F27: =Punisher1!F27-Deadpool2!F27 -> 0 | G27: =Punisher1!G27-Deadpool2!G27 -> 0 | H27: =Punisher1!H27-Deadpool2!H27 -> 1 | ... AD27: =Punisher1!AD27-Deadpool2!AD27 -> 0
A28: =Punisher1!A28-Deadpool2!A28 -> 0 | B28: =Punisher1!B28-Deadpool2!B28 -> 0 | C28: =Punisher1!C28-Deadpool2!C28 -> 0 | D28: =Punisher1!D28-Deadpool2!D28 -> 0 | E28: =Punisher1!E28-Deadpool2!E28 -> 0 | F28: =Punisher1!F28-Deadpool2!F28 -> 0 | G28: =Punisher1!G28-Deadpool2!G28 -> 0 | H28: =Punisher1!H28-Deadpool2!H28 -> 1 | ... AD28: =Punisher1!AD28-Deadpool2!AD28 -> 0
A29: =Punisher1!A29-Deadpool2!A29 -> 0 | B29: =Punisher1!B29-Deadpool2!B29 -> 0 | C29: =Punisher1!C29-Deadpool2!C29 -> 0 | D29: =Punisher1!D29-Deadpool2!D29 -> 0 | E29: =Punisher1!E29-Deadpool2!E29 -> 0 | F29: =Punisher1!F29-Deadpool2!F29 -> 0 | G29: =Punisher1!G29-Deadpool2!G29 -> 0 | H29: =Punisher1!H29-Deadpool2!H29 -> 1 | ... AD29: =Punisher1!AD29-Deadpool2!AD29 -> 0
A30: =Punisher1!A30-Deadpool2!A30 -> 0 | B30: =Punisher1!B30-Deadpool2!B30 -> 0 | C30: =Punisher1!C30-Deadpool2!C30 -> 0 | D30: =Punisher1!D30-Deadpool2!D30 -> 0 | E30: =Punisher1!E30-Deadpool2!E30 -> 0 | F30: =Punisher1!F30-Deadpool2!F30 -> 0 | G30: =Punisher1!G30-Deadpool2!G30 -> 0 | H30: =Punisher1!H30-Deadpool2!H30 -> 1 | ... AD30: =Punisher1!AD30-Deadpool2!AD30 -> 0

Sheet Multi-Escalar_Punisher1
A1: =2*Punisher1!A1 -> 0 | B1: =2*Punisher1!B1 -> 0 | C1: =2*Punisher1!C1 -> 0 | D1: =2*Punisher1!D1 -> 0 | E1: =2*Punisher1!E1 -> 0 | F1: =2*Punisher1!F1 -> 0 | G1: =2*Punisher1!G1 -> 0 | H1: =2*Punisher1!H1 -> 0 | ... AD1: =2*Punisher1!AD1 -> 0
A2: =2*Punisher1!A2 -> 0 | B2: =2*Punisher1!B2 -> 0 | C2: =2*Punisher1!C2 -> 0 | D2: =2*Punisher1!D2 -> 0 | E2: =2*Punisher1!E2 -> 0 | F2: =2*Punisher1!F2 -> 0 | G2: =2*Punisher1!G2 -> 0 | H2: =2*Punisher1!H2 -> 0 | ... AD2: =2*Punisher1!AD2 -> 0
A3: =2*Punisher1!A3 -> 0 | B3: =2*Punisher1!B3 -> 0 | C3: =2*Punisher1!C3 -> 0 | D3: =2*Punisher1!D3 -> 0 | E3: =2*Punisher1!E3 -> 0 | F3: =2*Punisher1!F3 -> 0 | G3: =2*Punisher1!G3 -> 0 | H3: =2*Punisher1!H3 -> 2 | ... AD3: =2*Punisher1!AD3 -> 0
A4: =2*Punisher1!A4 -> 0 | B4: =2*Punisher1!B4 -> 0 | C4: =2*Punisher1!C4 -> 0 | D4: =2*Punisher1!D4 -> 0 | E4: =2*Punisher1!E4 -> 0 | F4: =2*Punisher1!F4 -> 2 | G4: =2*Punisher1!G4 -> 2 | H4: =2*Punisher1!H4 -> 0 | ... AD4: =2*Punisher1!AD4 -> 0
A5: =2*Punisher1!A5 -> 0 | B5: =2*Punisher1!B5 -> 0 | C5: =2*Punisher1!C5 -> 0 | D5: =2*Punisher1!D5 -> 0 | E5: =2*Punisher1!E5 -> 2 | F5: =2*Punisher1!F5 -> 0 | G5: =2*Punisher1!G5 -> 0 | H5: =2*Punisher1!H5 -> 0 | ... AD5: =2*Punisher1!AD5 -> 0
A6: =2*Punisher1!A6 -> 0 | B6: =2*Punisher1!B6 -> 0 | C6: =2*Punisher1!C6 -> 0 | D6: =2*Punisher1!D6 -> 2 | E6: =2*Punisher1!E6 -> 0 | F6: =2*Punisher1!F6 -> 0 | G6: =2*Punisher1!G6 -> 0 | H6: =2*Punisher1!H6 -> 0 | ... AD6: =2*Punisher1!AD6 -> 0
A7: =2*Punisher1!A7 -> 0 | B7: =2*Punisher1!B7 -> 0 | C7: =2*Punisher1!C7 -> 2 | D7: =2*Punisher1!D7 -> 0 | E7: =2*Punisher1!E7 -> 0 | F7: =2*Punisher1!F7 -> 0 | G7: =2*Punisher1!G7 -> 0 | H7: =2*Punisher1!H7 -> 0 | ... AD7: =2*Punisher1!AD7 -> 0
A8: =2*Punisher1!A8 -> 0 | B8: =2*Punisher1!B8 -> 2 | C8: =2*Punisher1!C8 -> 0 | D8: =2*Punisher1!D8 -> 0 | E8: =2*Punisher1!E8 -> 0 | F8: =2*Punisher1!F8 -> 0 | G8: =2*Punisher1!G8 -> 0 | H8: =2*Punisher1!H8 -> 0 | ... AD8: =2*Punisher1!AD8 -> 0
A9: =2*Punisher1!A9 -> 0 | B9: =2*Punisher1!B9 -> 2 | C9: =2*Punisher1!C9 -> 0 | D9: =2*Punisher1!D9 -> 0 | E9: =2*Punisher1!E9 -> 0 | F9: =2*Punisher1!F9 -> 0 | G9: =2*Punisher1!G9 -> 0 | H9: =2*Punisher1!H9 -> 0 | ... AD9: =2*Punisher1!AD9 -> 0
A10: =2*Punisher1!A10 -> 0 | B10: =2*Punisher1!B10 -> 2 | C10: =2*Punisher1!C10 -> 0 | D10: =2*Punisher1!D10 -> 0 | E10: =2*Punisher1!E10 -> 0 | F10: =2*Punisher1!F10 -> 0 | G10: =2*Punisher1!G10 -> 0 | H10: =2*Punisher1!H10 -> 0 | ... AD10: =2*Punisher1!AD10 -> 0
A11: =2*Punisher1!A11 -> 0 | B11: =2*Punisher1!B11 -> 2 | C11: =2*Punisher1!C11 -> 0 | D11: =2*Punisher1!D11 -> 0 | E11: =2*Punisher1!E11 -> 0 | F11: =2*Punisher1!F11 -> 0 | G11: =2*Punisher1!G11 -> 0 | H11: =2*Punisher1!H11 -> 0 | ... AD11: =2*Punisher1!AD11 -> 0
A12: =2*Punisher1!A12 -> 0 | B12: =2*Punisher1!B12 -> 2 | C12: =2*Punisher1!C12 -> 0 | D12: =2*Punisher1!D12 -> 0 | E12: =2*Punisher1!E12 -> 0 | F12: =2*Punisher1!F12 -> 0 | G12: =2*Punisher1!G12 -> 0 | H12: =2*Punisher1!H12 -> 0 | ... AD12: =2*Punisher1!AD12 -> 0
... A30: =2*Punisher1!A30 -> 0 | B30: =2*Punisher1!B30 -> 0 | C30: =2*Punisher1!C30 -> 0 | D30: =2*Punisher1!D30 -> 0 | E30: =2*Punisher1!E30 -> 0 | F30: =2*Punisher1!F30 -> 0 | G30: =2*Punisher1!G30 -> 0 | H30: =2*Punisher1!H30 -> 2 | ... AD30: =2*Punisher1!AD30 -> 0

Sheet Combinacion_c1A_c2B
A1: =2*Punisher1!A1+3*Deadpool2!A1 -> 0 | B1: =2*Punisher1!B1+3*Deadpool2!B1 -> 0 | C1: =2*Punisher1!C1+3*Deadpool2!C1 -> 0 | D1: =2*Punisher1!D1+3*Deadpool2!D1 -> 0 | E1: =2*Punisher1!E1+3*Deadpool2!E1 -> 0 | F1: =2*Punisher1!F1+3*Deadpool2!F1 -> 0 | G1: =2*Punisher1!G1+3*Deadpool2!G1 -> 0 | H1: =2*Punisher1!H1+3*Deadpool2!H1 -> 0 | ... AD1: =2*Punisher1!AD1+3*Deadpool2!AD1 -> 0
A2: =2*Punisher1!A2+3*Deadpool2!A2 -> 0 | B2: =2*Punisher1!B2+3*Deadpool2!B2 -> 0 | C2: =2*Punisher1!C2+3*Deadpool2!C2 -> 0 | D2: =2*Punisher1!D2+3*Deadpool2!D2 -> 0 | E2: =2*Punisher1!E2+3*Deadpool2!E2 -> 0 | F2: =2*Punisher1!F2+3*Deadpool2!F2 -> 0 | G2: =2*Punisher1!G2+3*Deadpool2!G2 -> 0 | H2: =2*Punisher1!H2+3*Deadpool2!H2 -> 0 | ... AD2: =2*Punisher1!AD2+3*Deadpool2!AD2 -> 0
A3: =2*Punisher1!A3+3*Deadpool2!A3 -> 0 | B3: =2*Punisher1!B3+3*Deadpool2!B3 -> 0 | C3: =2*Punisher1!C3+3*Deadpool2!C3 -> 0 | D3: =2*Punisher1!D3+3*Deadpool2!D3 -> 0 | E3: =2*Punisher1!E3+3*Deadpool2!E3 -> 0 | F3: =2*Punisher1!F3+3*Deadpool2!F3 -> 0 | G3: =2*Punisher1!G3+3*Deadpool2!G3 -> 0 | H3: =2*Punisher1!H3+3*Deadpool2!H3 -> 2 | ... AD3: =2*Punisher1!AD3+3*Deadpool2!AD3 -> 0
A4: =2*Punisher1!A4+3*Deadpool2!A4 -> 0 | B4: =2*Punisher1!B4+3*Deadpool2!B4 -> 0 | C4: =2*Punisher1!C4+3*Deadpool2!C4 -> 0 | D4: =2*Punisher1!D4+3*Deadpool2!D4 -> 0 | E4: =2*Punisher1!E4+3*Deadpool2!E4 -> 0 | F4: =2*Punisher1!F4+3*Deadpool2!F4 -> 2 | G4: =2*Punisher1!G4+3*Deadpool2!G4 -> 2 | H4: =2*Punisher1!H4+3*Deadpool2!H4 -> 0 | ... AD4: =2*Punisher1!AD4+3*Deadpool2!AD4 -> 0
A5: =2*Punisher1!A5+3*Deadpool2!A5 -> 0 | B5: =2*Punisher1!B5+3*Deadpool2!B5 -> 0 | C5: =2*Punisher1!C5+3*Deadpool2!C5 -> 0 | D5: =2*Punisher1!D5+3*Deadpool2!D5 -> 0 | E5: =2*Punisher1!E5+3*Deadpool2!E5 -> 2 | F5: =2*Punisher1!F5+3*Deadpool2!F5 -> 0 | G5: =2*Punisher1!G5+3*Deadpool2!G5 -> 0 | H5: =2*Punisher1!H5+3*Deadpool2!H5 -> 6 | ... AD5: =2*Punisher1!AD5+3*Deadpool2!AD5 -> 0
A6: =2*Punisher1!A6+3*Deadpool2!A6 -> 0 | B6: =2*Punisher1!B6+3*Deadpool2!B6 -> 0 | C6: =2*Punisher1!C6+3*Deadpool2!C6 -> 0 | D6: =2*Punisher1!D6+3*Deadpool2!D6 -> 2 | E6: =2*Punisher1!E6+3*Deadpool2!E6 -> 0 | F6: =2*Punisher1!F6+3*Deadpool2!F6 -> 6 | G6: =2*Punisher1!G6+3*Deadpool2!G6 -> 6 | H6: =2*Punisher1!H6+3*Deadpool2!H6 -> 6 | ... AD6: =2*Punisher1!AD6+3*Deadpool2!AD6 -> 0
A7: =2*Punisher1!A7+3*Deadpool2!A7 -> 0 | B7: =2*Punisher1!B7+3*Deadpool2!B7 -> 0 | C7: =2*Punisher1!C7+3*Deadpool2!C7 -> 2 | D7: =2*Punisher1!D7+3*Deadpool2!D7 -> 0 | E7: =2*Punisher1!E7+3*Deadpool2!E7 -> 6 | F7: =2*Punisher1!F7+3*Deadpool2!F7 -> 6 | G7: =2*Punisher1!G7+3*Deadpool2!G7 -> 6 | H7: =2*Punisher1!H7+3*Deadpool2!H7 -> 6 | ... AD7: =2*Punisher1!AD7+3*Deadpool2!AD7 -> 0
A8: =2*Punisher1!A8+3*Deadpool2!A8 -> 0 | B8: =2*Punisher1!B8+3*Deadpool2!B8 -> 2 | C8: =2*Punisher1!C8+3*Deadpool2!C8 -> 0 | D8: =2*Punisher1!D8+3*Deadpool2!D8 -> 6 | E8: =2*Punisher1!E8+3*Deadpool2!E8 -> 6 | F8: =2*Punisher1!F8+3*Deadpool2!F8 -> 6 | G8: =2*Punisher1!G8+3*Deadpool2!G8 -> 6 | H8: =2*Punisher1!H8+3*Deadpool2!H8 -> 3 | ... AD8: =2*Punisher1!AD8+3*Deadpool2!AD8 -> 0
A9: =2*Punisher1!A9+3*Deadpool2!A9 -> 0 | B9: =2*Punisher1!B9+3*Deadpool2!B9 -> 2 | C9: =2*Punisher1!C9+3*Deadpool2!C9 -> 6 | D9: =2*Punisher1!D9+3*Deadpool2!D9 -> 6 | E9: =2*Punisher1!E9+3*Deadpool2!E9 -> 6 | F9: =2*Punisher1!F9+3*Deadpool2!F9 -> 3 | G9: =2*Punisher1!G9+3*Deadpool2!G9 -> 3 | H9: =2*Punisher1!H9+3*Deadpool2!H9 -> 3 | ... AD9: =2*Punisher1!AD9+3*Deadpool2!AD9 -> 0
A10: =2*Punisher1!A10+3*Deadpool2!A10 -> 0 | B10: =2*Punisher1!B10+3*Deadpool2!B10 -> 8 | C10: =2*Punisher1!C10+3*Deadpool2!C10 -> 6 | D10: =2*Punisher1!D10+3*Deadpool2!D10 -> 6 | E10: =2*Punisher1!E10+3*Deadpool2!E10 -> 6 | F10: =2*Punisher1!F10+3*Deadpool2!F10 -> 3 | G10: =2*Punisher1!G10+3*Deadpool2!G10 -> 3 | H10: =2*Punisher1!H10+3*Deadpool2!H10 -> 3 | ... AD10: =2*Punisher1!AD10+3*Deadpool2!AD10 -> 0
A11: =2*Punisher1!A11+3*Deadpool2!A11 -> 0 | B11: =2*Punisher1!B11+3*Deadpool2!B11 -> 8 | C11: =2*Punisher1!C11+3*Deadpool2!C11 -> 6 | D11: =2*Punisher1!D11+3*Deadpool2!D11 -> 6 | E11: =2*Punisher1!E11+3*Deadpool2!E11 -> 3 | F11: =2*Punisher1!F11+3*Deadpool2!F11 -> 3 | G11: =2*Punisher1!G11+3*Deadpool2!G11 -> 3 | H11: =2*Punisher1!H11+3*Deadpool2!H11 -> 3 | ... AD11: =2*Punisher1!AD11+3*Deadpool2!AD11 -> 0
A12: =2*Punisher1!A12+3*Deadpool2!A12 -> 0 | B12: =2*Punisher1!B12+3*Deadpool2!B12 -> 8 | C12: =2*Punisher1!C12+3*Deadpool2!C12 -> 6 | D12: =2*Punisher1!D12+3*Deadpool2!D12 -> 6 | E12: =2*Punisher1!E12+3*Deadpool2!E12 -> 3 | F12: =2*Punisher1!F12+3*Deadpool2!F12 -> 3 | G12: =2*Punisher1!G12+3*Deadpool2!G12 -> 3 | H12: =2*Punisher1!H12+3*Deadpool2!H12 -> 3 | ... AD12: =2*Punisher1!AD12+3*Deadpool2!AD12 -> 0
... A19: =2*Punisher1!A19+3*Deadpool2!A19 -> 0 | B19: =2*Punisher1!B19+3*Deadpool2!B19 -> 6 | C19: =2*Punisher1!C19+3*Deadpool2!C19 -> 6 | D19: =2*Punisher1!D19+3*Deadpool2!D19 -> 8 | E19: =2*Punisher1!E19+3*Deadpool2!E19 -> 3 | F19: =2*Punisher1!F19+3*Deadpool2!F19 -> 3 | G19: =2*Punisher1!G19+3*Deadpool2!G19 -> 0 | H19: =2*Punisher1!H19+3*Deadpool2!H19 -> 0 | ... AD19: =2*Punisher1!AD19+3*Deadpool2!AD19 -> 0
A20: =2*Punisher1!A20+3*Deadpool2!A20 -> 0 | B20: =2*Punisher1!B20+3*Deadpool2!B20 -> 6 | C20: =2*Punisher1!C20+3*Deadpool2!C20 -> 8 | D20: =2*Punisher1!D20+3*Deadpool2!D20 -> 6 | E20: =2*Punisher1!E20+3*Deadpool2!E20 -> 3 | F20: =2*Punisher1!F20+3*Deadpool2!F20 -> 5 | G20: =2*Punisher1!G20+3*Deadpool2!G20 -> 5 | H20: =2*Punisher1!H20+3*Deadpool2!H20 -> 2 | ... Q20: =2*Punisher1!Q20+3*Deadpool2!Q20 -> 5 | S20: =2*Punisher1!S20+3*Deadpool2!S20 -> 2 | T20: =2*Punisher1!T20+3*Deadpool2!T20 -> 2 | U20: =2*Punisher1!U20+3*Deadpool2!U20 -> 0 | V20: =2*Punisher1!V20+3*Deadpool2!V20 -> 0 | W20: =2*Punisher1!W20+3*Deadpool2!W20 -> 5 | X20: =2*Punisher1!X20+3*Deadpool2!X20 -> 3 | Y20: =2*Punisher1!Y20+3*Deadpool2!Y20 -> 3 | Z20: =2*Punisher1!Z20+3*Deadpool2!Z20 -> 6 | ... AD20: =2*Punisher1!AD20+3*Deadpool2!AD20 -> 0
A21: =2*Punisher1!A21+3*Deadpool2!A21 -> 0 | B21: =2*Punisher1!B21+3*Deadpool2!B21 -> 0 | C21: =2*Punisher1!C21+3*Deadpool2!C21 -> 8 | D21: =2*Punisher1!D21+3*Deadpool2!D21 -> 6 | E21: =2*Punisher1!E21+3*Deadpool2!E21 -> 6 | F21: =2*Punisher1!F21+3*Deadpool2!F21 -> 5 | G21: =2*Punisher1!G21+3*Deadpool2!G21 -> 5 | H21: =2*Punisher1!H21+3*Deadpool2!H21 -> 5 | ... AD21: =2*Punisher1!AD21+3*Deadpool2!AD21 -> 0
A22: =2*Punisher1!A22+3*Deadpool2!A22 -> 0 | B22: =2*Punisher1!B22+3*Deadpool2!B22 -> 0 | C22: =2*Punisher1!C22+3*Deadpool2!C22 -> 0 | D22: =2*Punisher1!D22+3*Deadpool2!D22 -> 6 | E22: =2*Punisher1!E22+3*Deadpool2!E22 -> 6 | F22: =2*Punisher1!F22+3*Deadpool2!F22 -> 3 | G22: =2*Punisher1!G22+3*Deadpool2!G22 -> 3 | H22: =2*Punisher1!H22+3*Deadpool2!H22 -> 5 | ... AD22: =2*Punisher1!AD22+3*Deadpool2!AD22 -> 0
A23: =2*Punisher1!A23+3*Deadpool2!A23 -> 0 | B23: =2*Punisher1!B23+3*Deadpool2!B23 -> 0 | C23: =2*Punisher1!C23+3*Deadpool2!C23 -> 0 | D23: =2*Punisher1!D23+3*Deadpool2!D23 -> 0 | E23: =2*Punisher1!E23+3*Deadpool2!E23 -> 6 | F23: =2*Punisher1!F23+3*Deadpool2!F23 -> 6 | G23: =2*Punisher1!G23+3*Deadpool2!G23 -> 6 | H23: =2*Punisher1!H23+3*Deadpool2!H23 -> 5 | ... AD23: =2*Punisher1!AD23+3*Deadpool2!AD23 -> 0
A24: =2*Punisher1!A24+3*Deadpool2!A24 -> 0 | B24: =2*Punisher1!B24+3*Deadpool2!B24 -> 0 | C24: =2*Punisher1!C24+3*Deadpool2!C24 -> 0 | D24: =2*Punisher1!D24+3*Deadpool2!D24 -> 0 | E24: =2*Punisher1!E24+3*Deadpool2!E24 -> 0 | F24: =2*Punisher1!F24+3*Deadpool2!F24 -> 6 | G24: =2*Punisher1!G24+3*Deadpool2!G24 -> 6 | H24: =2*Punisher1!H24+3*Deadpool2!H24 -> 8 | ... AD24: =2*Punisher1!AD24+3*Deadpool2!AD24 -> 0
A25: =2*Punisher1!A25+3*Deadpool2!A25 -> 0 | B25: =2*Punisher1!B25+3*Deadpool2!B25 -> 0 | C25: =2*Punisher1!C25+3*Deadpool2!C25 -> 0 | D25: =2*Punisher1!D25+3*Deadpool2!D25 -> 0 | E25: =2*Punisher1!E25+3*Deadpool2!E25 -> 0 | F25: =2*Punisher1!F25+3*Deadpool2!F25 -> 0 | G25: =2*Punisher1!G25+3*Deadpool2!G25 -> 6 | H25: =2*Punisher1!H25+3*Deadpool2!H25 -> 8 | ... AD25: =2*Punisher1!AD25+3*Deadpool2!AD25 -> 0
A26: =2*Punisher1!A26+3*Deadpool2!A26 -> 0 | B26: =2*Punisher1!B26+3*Deadpool2!B26 -> 0 | C26: =2*Punisher1!C26+3*Deadpool2!C26 -> 0 | D26: =2*Punisher1!D26+3*Deadpool2!D26 -> 0 | E26: =2*Punisher1!E26+3*Deadpool2!E26 -> 0 | F26: =2*Punisher1!F26+3*Deadpool2!F26 -> 0 | G26: =2*Punisher1!G26+3*Deadpool2!G26 -> 6 | H26: =2*Punisher1!H26+3*Deadpool2!H26 -> 8 | ... AD26: =2*Punisher1!AD26+3*Deadpool2!AD26 -> 0
A27: =2*Punisher1!A27+3*Deadpool2!A27 -> 0 | B27: =2*Punisher1!B27+3*Deadpool2!B27 -> 0 | C27: =2*Punisher1!C27+3*Deadpool2!C27 -> 0 | D27: =2*Punisher1!D27+3*Deadpool2!D27 -> 0 | E27: =2*Punisher1!E27+3*Deadpool2!E27 -> 0 | F27: =2*Punisher1!F27+3*Deadpool2!F27 -> 0 | G27: =2*Punisher1!G27+3*Deadpool2!G27 -> 0 | H27: =2*Punisher1!H27+3*Deadpool2!H27 -> 2 | ... AD27: =2*Punisher1!AD27+3*Deadpool2!AD27 -> 0
A28: =2*Punisher1!A28+3*Deadpool2!A28 -> 0 | B28: =2*Punisher1!B28+3*Deadpool2!B28 -> 0 | C28: =2*Punisher1!C28+3*Deadpool2!C28 -> 0 | D28: =2*Punisher1!D28+3*Deadpool2!D28 -> 0 | E28: =2*Punisher1!E28+3*Deadpool2!E28 -> 0 | F28: =2*Punisher1!F28+3*Deadpool2!F28 -> 0 | G28: =2*Punisher1!G28+3*Deadpool2!G28 -> 0 | H28: =2*Punisher1!H28+3*Deadpool2!H28 -> 2 | ... AD28: =2*Punisher1!AD28+3*Deadpool2!AD28 -> 0
A29: =2*Punisher1!A29+3*Deadpool2!A29 -> 0 | B29: =2*Punisher1!B29+3*Deadpool2!B29 -> 0 | C29: =2*Punisher1!C29+3*Deadpool2!C29 -> 0 | D29: =2*Punisher1!D29+3*Deadpool2!D29 -> 0 | E29: =2*Punisher1!E29+3*Deadpool2!E29 -> 0 | F29: =2*Punisher1!F29+3*Deadpool2!F29 -> 0 | G29: =2*Punisher1!G29+3*Deadpool2!G29 -> 0 | H29: =2*Punisher1!H29+3*Deadpool2!H29 -> 2 | ... AD29: =2*Punisher1!AD29+3*Deadpool2!AD29 -> 0
A30: =2*Punisher1!A30+3*Deadpool2!A30 -> 0 | B30: =2*Punisher1!B30+3*Deadpool2!B30 -> 0 | C30: =2*Punisher1!C30+3*Deadpool2!C30 -> 0 | D30: =2*Punisher1!D30+3*Deadpool2!D30 -> 0 | E30: =2*Punisher1!E30+3*Deadpool2!E30 -> 0 | F30: =2*Punisher1!F30+3*Deadpool2!F30 -> 0 | G30: =2*Punisher1!G30+3*Deadpool2!G30 -> 0 | H30: =2*Punisher1!H30+3*Deadpool2!H30 -> 2 | ... AD30: =2*Punisher1!AD30+3*Deadpool2!AD30 -> 0

Sheet Deadpool2
